Workbook

Sheet Week -1
F1: Week 1
F2: Set 1 | I2: Set 2 | L2: Set 3 | O2: Total Volume
A3: Day 1 | B3: Sets | C3: Rep Range | D3: RPE | E3: RP | F3: Load | G3: Reps | H3: MAX | I3: Load | J3: Reps | K3: MAX | L3: Load | M3: Reps | N3: MAX | O3: Volume (Load x Sets x Reps)
A4: Seated Chest Press Machine | B4: 3 | C4: 10–15 | E4: 60 | F4: 100 | G4: 11 | H4: =F4/(1.0278-(0.0278*G4)) -> 138.50416 | I4: 100 | J4: 9 | K4: =I4/(1.0278-(0.0278*J4)) -> 128.60082 | L4: 115 | M4: 8 | N4: =L4/(1.0278-(0.0278*M4)) -> 142.78619 | O4: =+F4*G4+I4*J4+L4*M4 -> 2920 | R4: =IF(OR(ISBLANK(O4), ISBLANK('WEEK 1'!O4)), "", (O4 - 'WEEK 1'!O4) & " " & IF(O4 - 'WEEK 1'!O4 > 0, "INCREASE", IF(O4 - 'WEEK 1'!O4 < 0, "DECREASE", "NO CHANGE"))) -> -370 DECREASE
A5: Tricep Cable Pushdown | B5: 3 | C5: 10–12 | E5: 60 | F5: 80 | G5: 8 | H5: =F5/(1.0278-(0.0278*G5)) -> 99.329526 | I5: 80 | J5: 8 | K5: =I5/(1.0278-(0.0278*J5)) -> 99.329526 | L5: 80 | M5: 6 | N5: =L5/(1.0278-(0.0278*M5)) -> 92.915215 | O5: =+F5*G5+I5*J5+L5*M5 -> 1760 | R5: =IF(OR(ISBLANK(O5), ISBLANK('WEEK 1'!O5)), "", (O5 - 'WEEK 1'!O5) & " " & IF(O5 - 'WEEK 1'!O5 > 0, "INCREASE", IF(O5 - 'WEEK 1'!O5 < 0, "DECREASE", "NO CHANGE"))) -> 365 INCREASE
A6: Seated Shoulder Press | B6: 3 | C6: 10–12 | E6: 60 | F6: 30 | G6: 8 | H6: =F6/(1.0278-(0.0278*G6)) -> 37.248572 | I6: 65 | J6: 6 | K6: =I6/(1.0278-(0.0278*J6)) -> 75.493612 | L6: 55 | M6: 8 | N6: =L6/(1.0278-(0.0278*M6)) -> 68.289049 | O6: =+F6*G6+I6*J6+L6*M6 -> 1070 | R6: =IF(OR(ISBLANK(O6), ISBLANK('WEEK 1'!O6)), "", (O6 - 'WEEK 1'!O6) & " " & IF(O6 - 'WEEK 1'!O6 > 0, "INCREASE", IF(O6 - 'WEEK 1'!O6 < 0, "DECREASE", "NO CHANGE"))) -> -485 DECREASE
A7: Tricep Dips (Assisted) | B7: 3 | C7: 8–10 | E7: 60 | F7: 50 | G7: 7 | H7: =F7/(1.0278-(0.0278*G7)) -> 60.009602 | I7: 70 | J7: 7 | K7: =I7/(1.0278-(0.0278*J7)) -> 84.013442 | L7: 70 | M7: 8 | N7: =L7/(1.0278-(0.0278*M7)) -> 86.913335 | O7: =+F7*G7+I7*J7+L7*M7 -> 1400 | R7: =IF(OR(ISBLANK(O7), ISBLANK('WEEK 1'!O7)), "", (O7 - 'WEEK 1'!O7) & " " & IF(O7 - 'WEEK 1'!O7 > 0, "INCREASE", IF(O7 - 'WEEK 1'!O7 < 0, "DECREASE", "NO CHANGE"))) -> 245 INCREASE
A8: Pectoral Fly | B8: 3 | C8: 8–12 | E8: 60 | F8: 100 | G8: 10 | H8: =F8/(1.0278-(0.0278*G8)) -> 133.3689 | I8: 115 | J8: 10 | K8: =I8/(1.0278-(0.0278*J8)) -> 153.37423 | L8: 115 | M8: 12 | N8: =L8/(1.0278-(0.0278*M8)) -> 165.65831 | O8: =+F8*G8+I8*J8+L8*M8 -> 3530 | R8: =IF(OR(ISBLANK(O8), ISBLANK('WEEK 1'!O8)), "", (O8 - 'WEEK 1'!O8) & " " & IF(O8 - 'WEEK 1'!O8 > 0, "INCREASE", IF(O8 - 'WEEK 1'!O8 < 0, "DECREASE", "NO CHANGE"))) -> 615 INCREASE
A9: Ab Twist machine | B9: 3 | C9: 12-15 | E9: 60 | H9: =F9/(1.0278-(0.0278*G9)) -> 0 | K9: =I9/(1.0278-(0.0278*J9)) -> 0 | N9: =L9/(1.0278-(0.0278*M9)) -> 0 | O9: =+F9*G9+I9*J9+L9*M9 -> 0 | R9: =IF(OR(ISBLANK(O9), ISBLANK('WEEK 1'!O9)), "", (O9 - 'WEEK 1'!O9) & " " & IF(O9 - 'WEEK 1'!O9 > 0, "INCREASE", IF(O9 - 'WEEK 1'!O9 < 0, "DECREASE", "NO CHANGE"))) -> -4360 DECREASE
A10: Day 2 | B10: Sets | C10: Rep Range | D10: RPE | E10: Rest Period | F10: Load | G10: Reps | H10: MAX | I10: Load | J10: Reps | K10: MAX | L10: Load | M10: Reps | N10: MAX | O10: Volume (Load x Sets x Reps)
A11: Row Machine | B11: 3 | C11: 8–10 | E11: 60 | F11: 100 | G11: 12 | H11: =F11/(1.0278-(0.0278*G11)) -> 144.05071 | I11: 115 | J11: 10 | K11: =I11/(1.0278-(0.0278*J11)) -> 153.37423 | L11: 115 | M11: 9 | N11: =L11/(1.0278-(0.0278*M11)) -> 147.89095 | O11: =+F11*G11+I11*J11+L11*M11 -> 3385 | R11: =IF(OR(ISBLANK(O11), ISBLANK('WEEK 1'!O11)), "", (O11 - 'WEEK 1'!O11) & " " & IF(O11 - 'WEEK 1'!O11 > 0, "INCREASE", IF(O11 - 'WEEK 1'!O11 < 0, "DECREASE", "NO CHANGE"))) -> -1235 DECREASE
A12: Wide grip Pull-Up (Assisted) | B12: 3 | C12: 10–15 | E12: 60 | H12: =F12/(1.0278-(0.0278*G12)) -> 0 | K12: =I12/(1.0278-(0.0278*J12)) -> 0 | N12: =L12/(1.0278-(0.0278*M12)) -> 0 | O12: =+F12*G12+I12*J12+L12*M12 -> 0 | R12: =IF(OR(ISBLANK(O12), ISBLANK('WEEK 1'!O12)), "", (O12 - 'WEEK 1'!O12) & " " & IF(O12 - 'WEEK 1'!O12 > 0, "INCREASE", IF(O12 - 'WEEK 1'!O12 < 0, "DECREASE", "NO CHANGE"))) -> 0 NO CHANGE
A13: Preacher Curl | B13: 3 | C13: 8–10 | E13: 60 | H13: =F13/(1.0278-(0.0278*G13)) -> 0 | K13: =I13/(1.0278-(0.0278*J13)) -> 0 | N13: =L13/(1.0278-(0.0278*M13)) -> 0 | O13: =+F13*G13+I13*J13+L13*M13 -> 0 | R13: =IF(OR(ISBLANK(O13), ISBLANK('WEEK 1'!O13)), "", (O13 - 'WEEK 1'!O13) & " " & IF(O13 - 'WEEK 1'!O13 > 0, "INCREASE", IF(O13 - 'WEEK 1'!O13 < 0, "DECREASE", "NO CHANGE"))) -> -3080 DECREASE
A14: Lat Pulldown | B14: 3 | C14: 8–10 | E14: 60 | F14: 140 | G14: 7 | H14: =F14/(1.0278-(0.0278*G14)) -> 168.02688 | I14: 140 | J14: 8 | K14: =I14/(1.0278-(0.0278*J14)) -> 173.82667 | L14: 140 | M14: 8 | N14: =L14/(1.0278-(0.0278*M14)) -> 173.82667 | O14: =+F14*G14+I14*J14+L14*M14 -> 3220 | R14: =IF(OR(ISBLANK(O14), ISBLANK('WEEK 1'!O14)), "", (O14 - 'WEEK 1'!O14) & " " & IF(O14 - 'WEEK 1'!O14 > 0, "INCREASE", IF(O14 - 'WEEK 1'!O14 < 0, "DECREASE", "NO CHANGE"))) -> 160 INCREASE
A15: Barbell Shrugs | B15: 3 | C15: 8–10 | E15: 60 | F15: 90 | G15: 13 | H15: =F15/(1.0278-(0.0278*G15)) -> 135.05402 | I15: 90 | J15: 14 | K15: =I15/(1.0278-(0.0278*J15)) -> 140.93329 | L15: 100 | M15: 12 | N15: =L15/(1.0278-(0.0278*M15)) -> 144.05071 | O15: =+F15*G15+I15*J15+L15*M15 -> 3630 | R15: =IF(OR(ISBLANK(O15), ISBLANK('WEEK 1'!O15)), "", (O15 - 'WEEK 1'!O15) & " " & IF(O15 - 'WEEK 1'!O15 > 0, "INCREASE", IF(O15 - 'WEEK 1'!O15 < 0, "DECREASE", "NO CHANGE"))) -> -50 DECREASE
A16: Cable Ab Curl | B16: 3 | C16: 10–15 | E16: 60 | F16: 57.5 | G16: 12 | H16: =F16/(1.0278-(0.0278*G16)) -> 82.829156 | I16: 72.5 | J16: 10 | K16: =I16/(1.0278-(0.0278*J16)) -> 96.692451 | L16: 80 | M16: 9 | N16: =L16/(1.0278-(0.0278*M16)) -> 102.88066 | O16: =+F16*G16+I16*J16+L16*M16 -> 2135 | R16: =IF(OR(ISBLANK(O16), ISBLANK('WEEK 1'!O16)), "", (O16 - 'WEEK 1'!O16) & " " & IF(O16 - 'WEEK 1'!O16 > 0, "INCREASE", IF(O16 - 'WEEK 1'!O16 < 0, "DECREASE", "NO CHANGE"))) -> 2135 INCREASE
A17: Day 3 | B17: Sets | C17: Rep Range | D17: RPE | E17: Rest Period | F17: Load | G17: Reps | H17: MAX | I17: Load | J17: Reps | K17: MAX | L17: Load | M17: Reps | N17: MAX | O17: Volume (Load x Sets x Reps)
A18: Rest - 10k Steps minimum | H18: =F18/(1.0278-(0.0278*G18)) -> 0 | K18: =I18/(1.0278-(0.0278*J18)) -> 0 | N18: =L18/(1.0278-(0.0278*M18)) -> 0 | O18: =+F18*G18+I18*J18+L18*M18+#REF!*#REF!+#REF!*#REF! -> #REF!
A19: Day 4 | B19: Sets | C19: Rep Range | D19: RPE | E19: Rest Period | F19: Load | G19: Reps | H19: MAX | I19: Load | J19: Reps | K19: MAX | L19: Load | M19: Reps | N19: MAX | O19: Volume (Load x Sets x Reps)
A20: Chest Press Machine | B20: 3 | C20: 8-12 | E20: 60 | F20: 100 | G20: 13 | H20: =F20/(1.0278-(0.0278*G20)) -> 150.06002 | I20: 115 | J20: 9 | K20: =I20/(1.0278-(0.0278*J20)) -> 147.89095 | L20: 130 | M20: 7 | N20: =L20/(1.0278-(0.0278*M20)) -> 156.02496 | O20: =+F20*G20+I20*J20+L20*M20 -> 3245 | R20: =IF(OR(ISBLANK(O20), ISBLANK('WEEK 1'!O20)), "", (O20 - 'WEEK 1'!O20) & " " & IF(O20 - 'WEEK 1'!O20 > 0, "INCREASE", IF(O20 - 'WEEK 1'!O20 < 0, "DECREASE", "NO CHANGE"))) -> -515 DECREASE
A21: Wide Grip Pull-Up (Assisted) | B21: 3 | C21: 8-12 | E21: 60 | H21: =F21/(1.0278-(0.0278*G21)) -> 0 | K21: =I21/(1.0278-(0.0278*J21)) -> 0 | N21: =L21/(1.0278-(0.0278*M21)) -> 0 | O21: =+F21*G21+I21*J21+L21*M21 -> 0 | R21: =IF(OR(ISBLANK(O21), ISBLANK('WEEK 1'!O21)), "", (O21 - 'WEEK 1'!O21) & " " & IF(O21 - 'WEEK 1'!O21 > 0, "INCREASE", IF(O21 - 'WEEK 1'!O21 < 0, "DECREASE", "NO CHANGE"))) -> -720 DECREASE
A22: Neck Flexion | B22: 3 | C22: 8-12 | E22: 60 | F22: 25 | G22: 8 | H22: =F22/(1.0278-(0.0278*G22)) -> 31.040477 | I22: 25 | J22: 10 | K22: =I22/(1.0278-(0.0278*J22)) -> 33.342225 | L22: 25 | M22: 10 | N22: =L22/(1.0278-(0.0278*M22)) -> 33.342225 | O22: =+F22*G22+I22*J22+L22*M22 -> 700 | R22: =IF(OR(ISBLANK(O22), ISBLANK('WEEK 1'!O22)), "", (O22 - 'WEEK 1'!O22) & " " & IF(O22 - 'WEEK 1'!O22 > 0, "INCREASE", IF(O22 - 'WEEK 1'!O22 < 0, "DECREASE", "NO CHANGE"))) -> -200 DECREASE
A23: Tricep Dips (Assisted) | B23: 3 | C23: 8-12 | E23: 60 | F23: 55 | G23: 6 | H23: =F23/(1.0278-(0.0278*G23)) -> 63.87921 | I23: 55 | J23: 5 | K23: =I23/(1.0278-(0.0278*J23)) -> 61.881188 | L23: 55 | M23: 7 | N23: =L23/(1.0278-(0.0278*M23)) -> 66.010562 | O23: =+F23*G23+I23*J23+L23*M23 -> 990 | R23: =IF(OR(ISBLANK(O23), ISBLANK('WEEK 1'!O23)), "", (O23 - 'WEEK 1'!O23) & " " & IF(O23 - 'WEEK 1'!O23 > 0, "INCREASE", IF(O23 - 'WEEK 1'!O23 < 0, "DECREASE", "NO CHANGE"))) -> -90 DECREASE
A24: Preacher Curl | B24: 3 | C24: 8-12 | E24: 60 | F24: 95 | G24: 12 | H24: =F24/(1.0278-(0.0278*G24)) -> 136.84817 | I24: 95 | J24: 12 | K24: =I24/(1.0278-(0.0278*J24)) -> 136.84817 | L24: 110 | M24: 10 | N24: =L24/(1.0278-(0.0278*M24)) -> 146.70579 | O24: =+F24*G24+I24*J24+L24*M24 -> 3380 | R24: =IF(OR(ISBLANK(O24), ISBLANK('WEEK 1'!O24)), "", (O24 - 'WEEK 1'!O24) & " " & IF(O24 - 'WEEK 1'!O24 > 0, "INCREASE", IF(O24 - 'WEEK 1'!O24 < 0, "DECREASE", "NO CHANGE"))) -> -95 DECREASE
A25: Day 5 | B25: Sets | C25: Rep Range | D25: RPE | E25: Rest Period | F25: Load | G25: Reps | H25: MAX | I25: Load | J25: Reps | K25: MAX | L25: Load | M25: Reps | N25: MAX | O25: Volume (Load x Sets x Reps)
A26: Squats | B26: 3 | C26: 8–10 | E26: 60 | F26: 20 | G26: 8 | H26: =F26/(1.0278-(0.0278*G26)) -> 24.832381 | I26: 40 | J26: 8 | K26: =I26/(1.0278-(0.0278*J26)) -> 49.664763 | L26: 50 | M26: 8 | N26: =L26/(1.0278-(0.0278*M26)) -> 62.080954 | O26: =+F26*G26+I26*J26+L26*M26 -> 880 | R26: =IF(OR(ISBLANK(O26), ISBLANK('WEEK 1'!O26)), "", (O26 - 'WEEK 1'!O26) & " " & IF(O26 - 'WEEK 1'!O26 > 0, "INCREASE", IF(O26 - 'WEEK 1'!O26 < 0, "DECREASE", "NO CHANGE"))) -> -600 DECREASE
A27: Barbell shrugs | B27: 3 | C27: 10–12 | E27: 60 | H27: =F27/(1.0278-(0.0278*G27)) -> 0 | K27: =I27/(1.0278-(0.0278*J27)) -> 0 | N27: =L27/(1.0278-(0.0278*M27)) -> 0 | O27: =+F27*G27+I27*J27+L27*M27 -> 0
A28: Roman chair | B28: 3 | C28: 12–15 | E28: 60 | H28: =F28/(1.0278-(0.0278*G28)) -> 0 | K28: =I28/(1.0278-(0.0278*J28)) -> 0 | N28: =L28/(1.0278-(0.0278*M28)) -> 0 | O28: =+F28*G28+I28*J28+L28*M28 -> 0 | R28: =IF(OR(ISBLANK(O28), ISBLANK('WEEK 1'!O28)), "", (O28 - 'WEEK 1'!O28) & " " & IF(O28 - 'WEEK 1'!O28 > 0, "INCREASE", IF(O28 - 'WEEK 1'!O28 < 0, "DECREASE", "NO CHANGE"))) -> -900 DECREASE
A29: Leg Curl Machine | B29: 3 | C29: 10–12 | E29: 60 | F29: 120 | G29: 10 | H29: =F29/(1.0278-(0.0278*G29)) -> 160.04268 | I29: 130 | J29: 11 | K29: =I29/(1.0278-(0.0278*J29)) -> 180.0554 | L29: 130 | M29: 12 | N29: =L29/(1.0278-(0.0278*M29)) -> 187.26592 | O29: =+F29*G29+I29*J29+L29*M29 -> 4190 | R29: =IF(OR(ISBLANK(O29), ISBLANK('WEEK 1'!O29)), "", (O29 - 'WEEK 1'!O29) & " " & IF(O29 - 'WEEK 1'!O29 > 0, "INCREASE", IF(O29 - 'WEEK 1'!O29 < 0, "DECREASE", "NO CHANGE"))) -> -425 DECREASE
A30: Hip Abduction | B30: 3 | C30: 10–12 | E30: 60 | F30: 235 | G30: 11 | H30: =F30/(1.0278-(0.0278*G30)) -> 325.48476 | I30: 235 | J30: 11 | K30: =I30/(1.0278-(0.0278*J30)) -> 325.48476 | L30: 220 | M30: 10 | N30: =L30/(1.0278-(0.0278*M30)) -> 293.41158 | O30: =+F30*G30+I30*J30+L30*M30 -> 7370 | R30: =IF(OR(ISBLANK(O30), ISBLANK('WEEK 1'!O30)), "", (O30 - 'WEEK 1'!O30) & " " & IF(O30 - 'WEEK 1'!O30 > 0, "INCREASE", IF(O30 - 'WEEK 1'!O30 < 0, "DECREASE", "NO CHANGE"))) -> 30 INCREASE
A31: Ab Twist Machine | B31: 3 | C31: 10–12 | E31: 60 | H31: =F31/(1.0278-(0.0278*G31)) -> 0 | K31: =I31/(1.0278-(0.0278*J31)) -> 0 | N31: =L31/(1.0278-(0.0278*M31)) -> 0 | O31: =+F31*G31+I31*J31+L31*M31 -> 0

Sheet WEEK 1
F1: Week 1
F2: Set 1 | I2: Set 2 | L2: Set 3 | O2: Total Volume
A3: Day 1 | B3: Sets | C3: Rep Range | D3: RPE | E3: Rest Period | F3: Load | G3: Reps | H3: MAX | I3: Load | J3: Reps | K3: MAX | L3: Load | M3: Reps | N3: MAX | O3: Volume (Load x Sets x Reps)
A4: Seated Chest Press Machine | B4: 3 | C4: 10–15 | E4: 60 | F4: 115 | G4: 12 | H4: =F4/(1.0278-(0.0278*G4)) -> 165.65831 | I4: 130 | J4: 8 | K4: =I4/(1.0278-(0.0278*J4)) -> 161.41048 | L4: 145 | M4: 6 | N4: =L4/(1.0278-(0.0278*M4)) -> 168.40883 | O4: =+F4*G4+I4*J4+L4*M4 -> 3290 | R4: =IF(OR(ISBLANK(O4), ISBLANK('Week -1'!O4)), "", (O4 - 'Week -1'!O4) & " " & IF(O4 - 'Week -1'!O4 > 0, "INCREASE", IF(O4 - 'Week -1'!O4 < 0, "DECREASE", "NO CHANGE"))) -> 370 INCREASE
A5: Tricep Cable Pushdown | B5: 3 | C5: 10–12 | E5: 60 | F5: 52.5 | G5: 6 | H5: =F5/(1.0278-(0.0278*G5)) -> 60.97561 | I5: 42.5 | J5: 12 | K5: =I5/(1.0278-(0.0278*J5)) -> 61.22155 | L5: 47.5 | M5: 12 | N5: =L5/(1.0278-(0.0278*M5)) -> 68.424085 | O5: =+F5*G5+I5*J5+L5*M5 -> 1395 | R5: =IF(OR(ISBLANK(O5), ISBLANK('Week -1'!O5)), "", (O5 - 'Week -1'!O5) & " " & IF(O5 - 'Week -1'!O5 > 0, "INCREASE", IF(O5 - 'Week -1'!O5 < 0, "DECREASE", "NO CHANGE"))) -> -365 DECREASE
A6: Seated Shoulder Press | B6: 3 | C6: 10–12 | E6: 60 | F6: 65 | G6: 10 | H6: =F6/(1.0278-(0.0278*G6)) -> 86.689784 | I6: 65 | J6: 8 | K6: =I6/(1.0278-(0.0278*J6)) -> 80.70524 | L6: 55 | M6: 7 | N6: =L6/(1.0278-(0.0278*M6)) -> 66.010562 | O6: =+F6*G6+I6*J6+L6*M6 -> 1555 | R6: =IF(OR(ISBLANK(O6), ISBLANK('Week -1'!O6)), "", (O6 - 'Week -1'!O6) & " " & IF(O6 - 'Week -1'!O6 > 0, "INCREASE", IF(O6 - 'Week -1'!O6 < 0, "DECREASE", "NO CHANGE"))) -> 485 INCREASE
A7: Tricep Dips (Assisted) | B7: 3 | C7: 8–10 | E7: 60 | F7: 55 | G7: 6 | H7: =F7/(1.0278-(0.0278*G7)) -> 63.87921 | I7: 55 | J7: 6 | K7: =I7/(1.0278-(0.0278*J7)) -> 63.87921 | L7: 55 | M7: 9 | N7: =L7/(1.0278-(0.0278*M7)) -> 70.730453 | O7: =+F7*G7+I7*J7+L7*M7 -> 1155 | R7: =IF(OR(ISBLANK(O7), ISBLANK('Week -1'!O7)), "", (O7 - 'Week -1'!O7) & " " & IF(O7 - 'Week -1'!O7 > 0, "INCREASE", IF(O7 - 'Week -1'!O7 < 0, "DECREASE", "NO CHANGE"))) -> -245 DECREASE
A8: Pectoral Fly | B8: 3 | C8: 8–12 | E8: 60 | F8: 115 | G8: 12 | H8: =F8/(1.0278-(0.0278*G8)) -> 165.65831 | I8: 130 | J8: 8 | K8: =I8/(1.0278-(0.0278*J8)) -> 161.41048 | L8: 165 | M8: 3 | N8: =L8/(1.0278-(0.0278*M8)) -> 174.7141 | O8: =+F8*G8+I8*J8+L8*M8 -> 2915 | R8: =IF(OR(ISBLANK(O8), ISBLANK('Week -1'!O8)), "", (O8 - 'Week -1'!O8) & " " & IF(O8 - 'Week -1'!O8 > 0, "INCREASE", IF(O8 - 'Week -1'!O8 < 0, "DECREASE", "NO CHANGE"))) -> -615 DECREASE
A9: Ab Twist machine | B9: 3 | C9: 12-15 | E9: 60 | F9: 130 | G9: 11 | H9: =F9/(1.0278-(0.0278*G9)) -> 180.0554 | I9: 130 | J9: 11 | K9: =I9/(1.0278-(0.0278*J9)) -> 180.0554 | L9: 150 | M9: 10 | N9: =L9/(1.0278-(0.0278*M9)) -> 200.05335 | O9: =+F9*G9+I9*J9+L9*M9 -> 4360
A10: Day 2 | B10: Sets | C10: Rep Range | D10: RPE | E10: Rest Period | F10: Load | G10: Reps | H10: MAX | I10: Load | J10: Reps | K10: MAX | L10: Load | M10: Reps | N10: MAX | O10: Volume (Load x Sets x Reps)
A11: Row Machine | B11: 3 | C11: 8–10 | E11: 60 | F11: 115 | G11: 14 | H11: =F11/(1.0278-(0.0278*G11)) -> 180.08143 | I11: 130 | J11: 12 | K11: =I11/(1.0278-(0.0278*J11)) -> 187.26592 | L11: 145 | M11: 10 | N11: =L11/(1.0278-(0.0278*M11)) -> 193.3849 | O11: =+F11*G11+I11*J11+L11*M11 -> 4620 | R11: =IF(OR(ISBLANK(O11), ISBLANK('Week -1'!O11)), "", (O11 - 'Week -1'!O11) & " " & IF(O11 - 'Week -1'!O11 > 0, "INCREASE", IF(O11 - 'Week -1'!O11 < 0, "DECREASE", "NO CHANGE"))) -> 1235 INCREASE
A12: Cable Face Pull | B12: 3 | C12: 10–15 | E12: 60 | H12: =F12/(1.0278-(0.0278*G12)) -> 0 | K12: =I12/(1.0278-(0.0278*J12)) -> 0 | N12: =L12/(1.0278-(0.0278*M12)) -> 0 | O12: =+F12*G12+I12*J12+L12*M12 -> 0 | R12: =IF(OR(ISBLANK(O12), ISBLANK('Week -1'!O12)), "", (O12 - 'Week -1'!O12) & " " & IF(O12 - 'Week -1'!O12 > 0, "INCREASE", IF(O12 - 'Week -1'!O12 < 0, "DECREASE", "NO CHANGE"))) -> 0 NO CHANGE
A13: Preacher Curl | B13: 3 | C13: 8–10 | E13: 60 | F13: 110 | G13: 10 | H13: =F13/(1.0278-(0.0278*G13)) -> 146.70579 | I13: 110 | J13: 9 | K13: =I13/(1.0278-(0.0278*J13)) -> 141.46091 | L13: 110 | M13: 9 | N13: =L13/(1.0278-(0.0278*M13)) -> 141.46091 | O13: =+F13*G13+I13*J13+L13*M13 -> 3080
A14: Lat Pulldown | B14: 3 | C14: 10–15 | E14: 60 | F14: 140 | G14: 9 | H14: =F14/(1.0278-(0.0278*G14)) -> 180.04115 | I14: 180 | J14: 3 | K14: =I14/(1.0278-(0.0278*J14)) -> 190.5972 | L14: 140 | M14: 9 | N14: =L14/(1.0278-(0.0278*M14)) -> 180.04115 | O14: =+F14*G14+I14*J14+L14*M14 -> 3060 | R14: =IF(OR(ISBLANK(O14), ISBLANK('Week -1'!O14)), "", (O14 - 'Week -1'!O14) & " " & IF(O14 - 'Week -1'!O14 > 0, "INCREASE", IF(O14 - 'Week -1'!O14 < 0, "DECREASE", "NO CHANGE"))) -> -160 DECREASE
A15: Barbell Shrugs | B15: 3 | C15: 8–10 | E15: 60 | F15: 90 | G15: 14 | H15: =F15/(1.0278-(0.0278*G15)) -> 140.93329 | I15: 110 | J15: 12 | K15: =I15/(1.0278-(0.0278*J15)) -> 158.45578 | L15: 110 | M15: 10 | N15: =L15/(1.0278-(0.0278*M15)) -> 146.70579 | O15: =+F15*G15+I15*J15+L15*M15 -> 3680 | R15: =IF(OR(ISBLANK(O15), ISBLANK('Week -1'!O15)), "", (O15 - 'Week -1'!O15) & " " & IF(O15 - 'Week -1'!O15 > 0, "INCREASE", IF(O15 - 'Week -1'!O15 < 0, "DECREASE", "NO CHANGE"))) -> 50 INCREASE
A16: Cable Ab Curl | B16: 3 | C16: 10–15 | E16: 60 | H16: =F16/(1.0278-(0.0278*G16)) -> 0 | K16: =I16/(1.0278-(0.0278*J16)) -> 0 | N16: =L16/(1.0278-(0.0278*M16)) -> 0 | O16: =+F16*G16+I16*J16+L16*M16 -> 0
A17: Day 3 | B17: Sets | C17: Rep Range | D17: RPE | E17: Rest Period | F17: Load | G17: Reps | H17: MAX | I17: Load | J17: Reps | K17: MAX | L17: Load | M17: Reps | N17: MAX | O17: Volume (Load x Sets x Reps)
A18: Rest - 10k Steps minimum | H18: =F18/(1.0278-(0.0278*G18)) -> 0 | K18: =I18/(1.0278-(0.0278*J18)) -> 0 | N18: =L18/(1.0278-(0.0278*M18)) -> 0 | O18: =+F18*G18+I18*J18+L18*M18+#REF!*#REF!+#REF!*#REF! -> #REF!
A19: Day 4 | B19: Sets | C19: Rep Range | D19: RPE | E19: Rest Period | F19: Load | G19: Reps | H19: MAX | I19: Load | J19: Reps | K19: MAX | L19: Load | M19: Reps | N19: MAX | O19: Volume (Load x Sets x Reps)
A20: Chest Press Machine | B20: 3 | C20: 8-12 | E20: 60 | F20: 130 | G20: 10 | H20: =F20/(1.0278-(0.0278*G20)) -> 173.37957 | I20: 130 | J20: 10 | K20: =I20/(1.0278-(0.0278*J20)) -> 173.37957 | L20: 145 | M20: 8 | N20: =L20/(1.0278-(0.0278*M20)) -> 180.03477 | O20: =+F20*G20+I20*J20+L20*M20 -> 3760 | R20: =IF(OR(ISBLANK(O20), ISBLANK('Week -1'!O20)), "", (O20 - 'Week -1'!O20) & " " & IF(O20 - 'Week -1'!O20 > 0, "INCREASE", IF(O20 - 'Week -1'!O20 < 0, "DECREASE", "NO CHANGE"))) -> 515 INCREASE
A21: Wide Grip Pull-Up (Assisted) | B21: 3 | C21: 8-12 | E21: 60 | F21: 40 | G21: 8 | H21: =F21/(1.0278-(0.0278*G21)) -> 49.664763 | I21: 40 | J21: 5 | K21: =I21/(1.0278-(0.0278*J21)) -> 45.0045 | L21: 40 | M21: 5 | N21: =L21/(1.0278-(0.0278*M21)) -> 45.0045 | O21: =+F21*G21+I21*J21+L21*M21 -> 720 | R21: =IF(OR(ISBLANK(O21), ISBLANK('Week -1'!O21)), "", (O21 - 'Week -1'!O21) & " " & IF(O21 - 'Week -1'!O21 > 0, "INCREASE", IF(O21 - 'Week -1'!O21 < 0, "DECREASE", "NO CHANGE"))) -> 720 INCREASE
A22: Neck Flexion | B22: 3 | C22: 8-12 | E22: 60 | F22: 25 | G22: 12 | H22: =F22/(1.0278-(0.0278*G22)) -> 36.012676 | I22: 25 | J22: 12 | K22: =I22/(1.0278-(0.0278*J22)) -> 36.012676 | L22: 25 | M22: 12 | N22: =L22/(1.0278-(0.0278*M22)) -> 36.012676 | O22: =+F22*G22+I22*J22+L22*M22 -> 900 | R22: =IF(OR(ISBLANK(O22), ISBLANK('Week -1'!O22)), "", (O22 - 'Week -1'!O22) & " " & IF(O22 - 'Week -1'!O22 > 0, "INCREASE", IF(O22 - 'Week -1'!O22 < 0, "DECREASE", "NO CHANGE"))) -> 200 INCREASE
A23: Tricep Dips (Assisted) | B23: 3 | C23: 8-12 | E23: 60 | F23: 40 | G23: 8 | H23: =F23/(1.0278-(0.0278*G23)) -> 49.664763 | I23: 40 | J23: 9 | K23: =I23/(1.0278-(0.0278*J23)) -> 51.440329 | L23: 40 | M23: 10 | N23: =L23/(1.0278-(0.0278*M23)) -> 53.347559 | O23: =+F23*G23+I23*J23+L23*M23 -> 1080 | R23: =IF(OR(ISBLANK(O23), ISBLANK('Week -1'!O23)), "", (O23 - 'Week -1'!O23) & " " & IF(O23 - 'Week -1'!O23 > 0, "INCREASE", IF(O23 - 'Week -1'!O23 < 0, "DECREASE", "NO CHANGE"))) -> 90 INCREASE
A24: Preacher Curl | B24: 3 | C24: 8-12 | E24: 60 | F24: 125 | G24: 12 | H24: =F24/(1.0278-(0.0278*G24)) -> 180.06338 | I24: 125 | J24: 7 | K24: =I24/(1.0278-(0.0278*J24)) -> 150.024 | L24: 110 | M24: 10 | N24: =L24/(1.0278-(0.0278*M24)) -> 146.70579 | O24: =+F24*G24+I24*J24+L24*M24 -> 3475 | R24: =IF(OR(ISBLANK(O24), ISBLANK('Week -1'!O24)), "", (O24 - 'Week -1'!O24) & " " & IF(O24 - 'Week -1'!O24 > 0, "INCREASE", IF(O24 - 'Week -1'!O24 < 0, "DECREASE", "NO CHANGE"))) -> 95 INCREASE
A25: Day 5 | B25: Sets | C25: Rep Range | D25: RPE | E25: Rest Period | F25: Load | G25: Reps | H25: MAX | I25: Load | J25: Reps | K25: MAX | L25: Load | M25: Reps | N25: MAX | O25: Volume (Load x Sets x Reps)
A26: Squats | B26: 3 | C26: 8–10 | E26: 60 | F26: 45 | G26: 10 | H26: =F26/(1.0278-(0.0278*G26)) -> 60.016004 | I26: 65 | J26: 8 | K26: =I26/(1.0278-(0.0278*J26)) -> 80.70524 | L26: 85 | M26: 6 | N26: =L26/(1.0278-(0.0278*M26)) -> 98.722416 | O26: =+F26*G26+I26*J26+L26*M26 -> 1480 | R26: =IF(OR(ISBLANK(O26), ISBLANK('Week -1'!O26)), "", (O26 - 'Week -1'!O26) & " " & IF(O26 - 'Week -1'!O26 > 0, "INCREASE", IF(O26 - 'Week -1'!O26 < 0, "DECREASE", "NO CHANGE"))) -> 600 INCREASE
A27: Seated Leg Extension | B27: 3 | C27: 10–12 | E27: 60 | F27: 160 | G27: 10 | H27: =F27/(1.0278-(0.0278*G27)) -> 213.39024 | I27: 160 | J27: 10 | K27: =I27/(1.0278-(0.0278*J27)) -> 213.39024 | L27: 145 | M27: 10 | N27: =L27/(1.0278-(0.0278*M27)) -> 193.3849 | O27: =+F27*G27+I27*J27+L27*M27 -> 4650
A28: Roman chair | B28: 3 | C28: 12–15 | E28: 60 | F28: 25 | G28: 12 | H28: =F28/(1.0278-(0.0278*G28)) -> 36.012676 | I28: 25 | J28: 12 | K28: =I28/(1.0278-(0.0278*J28)) -> 36.012676 | L28: 25 | M28: 12 | N28: =L28/(1.0278-(0.0278*M28)) -> 36.012676 | O28: =+F28*G28+I28*J28+L28*M28 -> 900 | R28: =IF(OR(ISBLANK(O28), ISBLANK('Week -1'!O28)), "", (O28 - 'Week -1'!O28) & " " & IF(O28 - 'Week -1'!O28 > 0, "INCREASE", IF(O28 - 'Week -1'!O28 < 0, "DECREASE", "NO CHANGE"))) -> 900 INCREASE
A29: Leg Curl Machine | B29: 3 | C29: 10–12 | E29: 60 | F29: 175 | G29: 9 | H29: =F29/(1.0278-(0.0278*G29)) -> 225.05144 | I29: 160 | J29: 10 | K29: =I29/(1.0278-(0.0278*J29)) -> 213.39024 | L29: 160 | M29: 9 | N29: =L29/(1.0278-(0.0278*M29)) -> 205.76132 | O29: =+F29*G29+I29*J29+L29*M29 -> 4615 | R29: =IF(OR(ISBLANK(O29), ISBLANK('Week -1'!O29)), "", (O29 - 'Week -1'!O29) & " " & IF(O29 - 'Week -1'!O29 > 0, "INCREASE", IF(O29 - 'Week -1'!O29 < 0, "DECREASE", "NO CHANGE"))) -> 425 INCREASE
A30: Hip abduction | B30: 3 | C30: 8-12 | E30: 60 | F30: 235 | G30: 10 | H30: =F30/(1.0278-(0.0278*G30)) -> 313.41691 | I30: 235 | J30: 10 | K30: =I30/(1.0278-(0.0278*J30)) -> 313.41691 | L30: 220 | M30: 12 | N30: =L30/(1.0278-(0.0278*M30)) -> 316.91155 | O30: =+F30*G30+I30*J30+L30*M30 -> 7340 | R30: =IF(OR(ISBLANK(O30), ISBLANK('Week -1'!O30)), "", (O30 - 'Week -1'!O30) & " " & IF(O30 - 'Week -1'!O30 > 0, "INCREASE", IF(O30 - 'Week -1'!O30 < 0, "DECREASE", "NO CHANGE"))) -> -30 DECREASE
A31: Hip Adduction | B31: 3 | C31: 10–12 | E31: 60 | F31: 250 | G31: 14 | H31: =F31/(1.0278-(0.0278*G31)) -> 391.48137 | I31: 305 | J31: 18 | K31: =I31/(1.0278-(0.0278*J31)) -> 578.30868 | L31: 305 | M31: 11 | N31: =L31/(1.0278-(0.0278*M31)) -> 422.43767 | O31: =+F31*G31+I31*J31+L31*M31 -> 12345

Sheet WEEK 2
F1: Week 1
F2: Set 1 | I2: Set 2 | L2: Set 3 | O2: Total Volume
A3: Day 1 | B3: Sets | C3: Rep Range | D3: RPE | E3: Rest Period | F3: Load | G3: Reps | H3: MAX | I3: Load | J3: Reps | K3: MAX | L3: Load | M3: Reps | N3: MAX | O3: Volume (Load x Sets x Reps)
A4: Seated Chest Press Machine | B4: 3 | C4: 10–15 | E4: 60 | F4: 145 | G4: 10 | H4: =F4/(1.0278-(0.0278*G4)) -> 193.3849 | I4: 145 | J4: 10 | K4: =I4/(1.0278-(0.0278*J4)) -> 193.3849 | L4: 160 | M4: 6 | N4: =L4/(1.0278-(0.0278*M4)) -> 185.83043 | O4: =+F4*G4+I4*J4+L4*M4 -> 3860 | R4: =IF(OR(ISBLANK(N4), ISBLANK('WEEK 1'!N4)), "", ROUNDUP(N4 - 'WEEK 1'!N4, 0) & " " & IF(N4 - 'WEEK 1'!N4 > 0, "INCREASE", IF(N4 - 'WEEK 1'!N4 < 0, "DECREASE", "NO CHANGE"))) -> 18 INCREASE
A5: Tricep Cable Pushdown rope | B5: 3 | C5: 10–12 | E5: 60 | F5: 52.5 | G5: 12 | H5: =F5/(1.0278-(0.0278*G5)) -> 75.626621 | I5: 42.5 | J5: 10 | K5: =I5/(1.0278-(0.0278*J5)) -> 56.681782 | L5: 42.5 | M5: 11 | N5: =L5/(1.0278-(0.0278*M5)) -> 58.864266 | O5: =+F5*G5+I5*J5+L5*M5 -> 1522.5 | R5: =IF(OR(ISBLANK(N5), ISBLANK('WEEK 1'!N5)), "", ROUNDUP(N5 - 'WEEK 1'!N5, 0) & " " & IF(N5 - 'WEEK 1'!N5 > 0, "INCREASE", IF(N5 - 'WEEK 1'!N5 < 0, "DECREASE", "NO CHANGE"))) -> -10 DECREASE
A6: Seated Shoulder Press | B6: 3 | C6: 10–12 | E6: 60 | F6: 65 | G6: 9 | H6: =F6/(1.0278-(0.0278*G6)) -> 83.590535 | I6: 65 | J6: 8 | K6: =I6/(1.0278-(0.0278*J6)) -> 80.70524 | L6: 65 | M6: 7 | N6: =L6/(1.0278-(0.0278*M6)) -> 78.012482 | O6: =+F6*G6+I6*J6+L6*M6 -> 1560 | R6: =IF(OR(ISBLANK(N6), ISBLANK('WEEK 1'!N6)), "", ROUNDUP(N6 - 'WEEK 1'!N6, 0) & " " & IF(N6 - 'WEEK 1'!N6 > 0, "INCREASE", IF(N6 - 'WEEK 1'!N6 < 0, "DECREASE", "NO CHANGE"))) -> 13 INCREASE
A7: Dumbbell side lateral raise | B7: 3 | C7: 8–10 | E7: 60 | F7: 20 | G7: 7 | H7: =F7/(1.0278-(0.0278*G7)) -> 24.003841 | I7: 15 | J7: 10 | K7: =I7/(1.0278-(0.0278*J7)) -> 20.005335 | L7: 15 | M7: 10 | N7: =L7/(1.0278-(0.0278*M7)) -> 20.005335 | O7: =+F7*G7+I7*J7+L7*M7 -> 440 | R7: =IF(OR(ISBLANK(H4), ISBLANK(K4), ISBLANK(N4), ISBLANK('WEEK 2'!N4)), "", ROUNDUP(((H4 + K4 + N4) / 3) - 'WEEK 2'!N4, 0) & " " & IF(((H4 + K4 + N4) / 3) - 'WEEK 2'!N4 > 0, "INCREASE", IF(((H4 + K4 + N4) / 3) - 'WEEK 2'!N4 < 0, "DECREASE", "NO CHANGE"))) -> 6 INCREASE
A8: Pectoral Fly | B8: 3 | C8: 8–12 | E8: 60 | F8: 160 | G8: 5 | H8: =F8/(1.0278-(0.0278*G8)) -> 180.018 | I8: 150 | J8: 6 | K8: =I8/(1.0278-(0.0278*J8)) -> 174.21603 | L8: 145 | M8: 8 | N8: =L8/(1.0278-(0.0278*M8)) -> 180.03477 | O8: =+F8*G8+I8*J8+L8*M8 -> 2860 | R8: =IF(OR(ISBLANK(N8), ISBLANK('WEEK 1'!N8)), "", ROUNDUP(N8 - 'WEEK 1'!N8, 0) & " " & IF(N8 - 'WEEK 1'!N8 > 0, "INCREASE", IF(N8 - 'WEEK 1'!N8 < 0, "DECREASE", "NO CHANGE"))) -> 6 INCREASE
A9: Ab Twist machine | B9: 3 | C9: 12-15 | E9: 60 | F9: 130 | G9: 11 | H9: =F9/(1.0278-(0.0278*G9)) -> 180.0554 | I9: 145 | J9: 10 | K9: =I9/(1.0278-(0.0278*J9)) -> 193.3849 | L9: 150 | M9: 10 | N9: =L9/(1.0278-(0.0278*M9)) -> 200.05335 | O9: =+F9*G9+I9*J9+L9*M9 -> 4380 | R9: =IF(OR(ISBLANK(N9), ISBLANK('WEEK 1'!N9)), "", ROUNDUP(N9 - 'WEEK 1'!N9, 0) & " " & IF(N9 - 'WEEK 1'!N9 > 0, "INCREASE", IF(N9 - 'WEEK 1'!N9 < 0, "DECREASE", "NO CHANGE"))) -> 0 NO CHANGE
A10: Day 2 | B10: Sets | C10: Rep Range | D10: RPE | E10: Rest Period | F10: Load | G10: Reps | H10: MAX | I10: Load | J10: Reps | K10: MAX | L10: Load | M10: Reps | N10: MAX | O10: Volume (Load x Sets x Reps) | R10: =IF(OR(ISBLANK(N10), ISBLANK('WEEK 1'!N10)), "", ROUNDUP(N10 - 'WEEK 1'!N10, 0) & " " & IF(N10 - 'WEEK 1'!N10 > 0, "INCREASE", IF(N10 - 'WEEK 1'!N10 < 0, "DECREASE", "NO CHANGE"))) -> #VALUE!
A11: Row Machine | B11: 3 | C11: 8–10 | E11: 60 | F11: 145 | G11: 10 | H11: =F11/(1.0278-(0.0278*G11)) -> 193.3849 | I11: 145 | J11: 10 | K11: =I11/(1.0278-(0.0278*J11)) -> 193.3849 | L11: 160 | M11: 12 | N11: =L11/(1.0278-(0.0278*M11)) -> 230.48113 | O11: =+F11*G11+I11*J11+L11*M11 -> 4820 | R11: =IF(OR(ISBLANK(N11), ISBLANK('WEEK 1'!N11)), "", ROUNDUP(N11 - 'WEEK 1'!N11, 0) & " " & IF(N11 - 'WEEK 1'!N11 > 0, "INCREASE", IF(N11 - 'WEEK 1'!N11 < 0, "DECREASE", "NO CHANGE"))) -> 38 INCREASE
A12: Wide grip Pull-Up (Assisted) | B12: 3 | C12: 10–15 | E12: 60 | F12: 40 | G12: 6 | H12: =F12/(1.0278-(0.0278*G12)) -> 46.457607 | K12: =I12/(1.0278-(0.0278*J12)) -> 0 | N12: =L12/(1.0278-(0.0278*M12)) -> 0 | O12: =+F12*G12+I12*J12+L12*M12 -> 240 | R12: =IF(OR(ISBLANK(N12), ISBLANK('WEEK 1'!N12)), "", ROUNDUP(N12 - 'WEEK 1'!N12, 0) & " " & IF(N12 - 'WEEK 1'!N12 > 0, "INCREASE", IF(N12 - 'WEEK 1'!N12 < 0, "DECREASE", "NO CHANGE"))) -> 0 NO CHANGE
A13: Preacher Curl | B13: 3 | C13: 8–10 | E13: 60 | F13: 125 | G13: 12 | H13: =F13/(1.0278-(0.0278*G13)) -> 180.06338 | I13: 125 | J13: 8 | K13: =I13/(1.0278-(0.0278*J13)) -> 155.20238 | L13: 125 | M13: 7 | N13: =L13/(1.0278-(0.0278*M13)) -> 150.024 | O13: =+F13*G13+I13*J13+L13*M13 -> 3375 | R13: =IF(OR(ISBLANK(N13), ISBLANK('WEEK 1'!N13)), "", ROUNDUP(N13 - 'WEEK 1'!N13, 0) & " " & IF(N13 - 'WEEK 1'!N13 > 0, "INCREASE", IF(N13 - 'WEEK 1'!N13 < 0, "DECREASE", "NO CHANGE"))) -> 9 INCREASE
A14: Lat Pulldown | B14: 3 | C14: 8–10 | E14: 60 | H14: =F14/(1.0278-(0.0278*G14)) -> 0 | K14: =I14/(1.0278-(0.0278*J14)) -> 0 | N14: =L14/(1.0278-(0.0278*M14)) -> 0 | O14: =+F14*G14+I14*J14+L14*M14 -> 0 | R14: =IF(OR(ISBLANK(N14), ISBLANK('WEEK 1'!N14)), "", ROUNDUP(N14 - 'WEEK 1'!N14, 0) & " " & IF(N14 - 'WEEK 1'!N14 > 0, "INCREASE", IF(N14 - 'WEEK 1'!N14 < 0, "DECREASE", "NO CHANGE"))) -> -181 DECREASE
A15: Barbell Shrugs | B15: 3 | C15: 8–10 | E15: 60 | F15: 110 | G15: 15 | H15: =F15/(1.0278-(0.0278*G15)) -> 180.09168 | I15: 110 | J15: 12 | K15: =I15/(1.0278-(0.0278*J15)) -> 158.45578 | L15: 110 | M15: 13 | N15: =L15/(1.0278-(0.0278*M15)) -> 165.06603 | O15: =+F15*G15+I15*J15+L15*M15 -> 4400 | R15: =IF(OR(ISBLANK(N15), ISBLANK('WEEK 1'!N15)), "", ROUNDUP(N15 - 'WEEK 1'!N15, 0) & " " & IF(N15 - 'WEEK 1'!N15 > 0, "INCREASE", IF(N15 - 'WEEK 1'!N15 < 0, "DECREASE", "NO CHANGE"))) -> 19 INCREASE
A16: Cable Ab Curl | B16: 3 | C16: 10–15 | E16: 60 | F16: 87.5 | G16: 10 | H16: =F16/(1.0278-(0.0278*G16)) -> 116.69779 | I16: 80 | J16: 13 | K16: =I16/(1.0278-(0.0278*J16)) -> 120.04802 | L16: 80 | M16: 12 | N16: =L16/(1.0278-(0.0278*M16)) -> 115.24056 | O16: =+F16*G16+I16*J16+L16*M16 -> 2875 | R16: =IF(OR(ISBLANK(N16), ISBLANK('WEEK 1'!N16)), "", ROUNDUP(N16 - 'WEEK 1'!N16, 0) & " " & IF(N16 - 'WEEK 1'!N16 > 0, "INCREASE", IF(N16 - 'WEEK 1'!N16 < 0, "DECREASE", "NO CHANGE"))) -> 116 INCREASE
A17: Day 3 | B17: Sets | C17: Rep Range | D17: RPE | E17: Rest Period | F17: Load | G17: Reps | H17: MAX | I17: Load | J17: Reps | K17: MAX | L17: Load | M17: Reps | N17: MAX | O17: Volume (Load x Sets x Reps) | R17: =IF(OR(ISBLANK(N17), ISBLANK('WEEK 1'!N17)), "", ROUNDUP(N17 - 'WEEK 1'!N17, 0) & " " & IF(N17 - 'WEEK 1'!N17 > 0, "INCREASE", IF(N17 - 'WEEK 1'!N17 < 0, "DECREASE", "NO CHANGE"))) -> #VALUE!
A18: Rest - 10k Steps minimum | H18: =F18/(1.0278-(0.0278*G18)) -> 0 | K18: =I18/(1.0278-(0.0278*J18)) -> 0 | N18: =L18/(1.0278-(0.0278*M18)) -> 0 | O18: =+F18*G18+I18*J18+L18*M18+#REF!*#REF!+#REF!*#REF! -> #REF! | R18: =IF(OR(ISBLANK(N18), ISBLANK('WEEK 1'!N18)), "", ROUNDUP(N18 - 'WEEK 1'!N18, 0) & " " & IF(N18 - 'WEEK 1'!N18 > 0, "INCREASE", IF(N18 - 'WEEK 1'!N18 < 0, "DECREASE", "NO CHANGE"))) -> 0 NO CHANGE
A19: Day 4 | B19: Sets | C19: Rep Range | D19: RPE | E19: Rest Period | F19: Load | G19: Reps | H19: MAX | I19: Load | J19: Reps | K19: MAX | L19: Load | M19: Reps | N19: MAX | O19: Volume (Load x Sets x Reps) | R19: =IF(OR(ISBLANK(N19), ISBLANK('WEEK 1'!N19)), "", ROUNDUP(N19 - 'WEEK 1'!N19, 0) & " " & IF(N19 - 'WEEK 1'!N19 > 0, "INCREASE", IF(N19 - 'WEEK 1'!N19 < 0, "DECREASE", "NO CHANGE"))) -> #VALUE!
A20: Chest Press Machine | B20: 3 | C20: 8-12 | E20: 60 | H20: =F20/(1.0278-(0.0278*G20)) -> 0 | K20: =I20/(1.0278-(0.0278*J20)) -> 0 | N20: =L20/(1.0278-(0.0278*M20)) -> 0 | O20: =+F20*G20+I20*J20+L20*M20 -> 0 | R20: =IF(OR(ISBLANK(N20), ISBLANK('WEEK 1'!N20)), "", ROUNDUP(N20 - 'WEEK 1'!N20, 0) & " " & IF(N20 - 'WEEK 1'!N20 > 0, "INCREASE", IF(N20 - 'WEEK 1'!N20 < 0, "DECREASE", "NO CHANGE"))) -> -181 DECREASE
A21: Wide Grip Pull-Up (Assisted) | B21: 3 | C21: 8-12 | E21: 60 | H21: =F21/(1.0278-(0.0278*G21)) -> 0 | K21: =I21/(1.0278-(0.0278*J21)) -> 0 | N21: =L21/(1.0278-(0.0278*M21)) -> 0 | O21: =+F21*G21+I21*J21+L21*M21 -> 0 | R21: =IF(OR(ISBLANK(N21), ISBLANK('WEEK 1'!N21)), "", ROUNDUP(N21 - 'WEEK 1'!N21, 0) & " " & IF(N21 - 'WEEK 1'!N21 > 0, "INCREASE", IF(N21 - 'WEEK 1'!N21 < 0, "DECREASE", "NO CHANGE"))) -> -46 DECREASE
A22: Neck Flexion | B22: 3 | C22: 8-12 | E22: 60 | H22: =F22/(1.0278-(0.0278*G22)) -> 0 | K22: =I22/(1.0278-(0.0278*J22)) -> 0 | N22: =L22/(1.0278-(0.0278*M22)) -> 0 | O22: =+F22*G22+I22*J22+L22*M22 -> 0 | R22: =IF(OR(ISBLANK(N22), ISBLANK('WEEK 1'!N22)), "", ROUNDUP(N22 - 'WEEK 1'!N22, 0) & " " & IF(N22 - 'WEEK 1'!N22 > 0, "INCREASE", IF(N22 - 'WEEK 1'!N22 < 0, "DECREASE", "NO CHANGE"))) -> -37 DECREASE
A23: Tricep Dips (Assisted) | B23: 3 | C23: 8-12 | E23: 60 | H23: =F23/(1.0278-(0.0278*G23)) -> 0 | K23: =I23/(1.0278-(0.0278*J23)) -> 0 | N23: =L23/(1.0278-(0.0278*M23)) -> 0 | O23: =+F23*G23+I23*J23+L23*M23 -> 0 | R23: =IF(OR(ISBLANK(N23), ISBLANK('WEEK 1'!N23)), "", ROUNDUP(N23 - 'WEEK 1'!N23, 0) & " " & IF(N23 - 'WEEK 1'!N23 > 0, "INCREASE", IF(N23 - 'WEEK 1'!N23 < 0, "DECREASE", "NO CHANGE"))) -> -54 DECREASE
A24: Preacher Curl | B24: 3 | C24: 8-12 | E24: 60 | H24: =F24/(1.0278-(0.0278*G24)) -> 0 | K24: =I24/(1.0278-(0.0278*J24)) -> 0 | N24: =L24/(1.0278-(0.0278*M24)) -> 0 | O24: =+F24*G24+I24*J24+L24*M24 -> 0 | R24: =IF(OR(ISBLANK(N24), ISBLANK('WEEK 1'!N24)), "", ROUNDUP(N24 - 'WEEK 1'!N24, 0) & " " & IF(N24 - 'WEEK 1'!N24 > 0, "INCREASE", IF(N24 - 'WEEK 1'!N24 < 0, "DECREASE", "NO CHANGE"))) -> -147 DECREASE
A25: Day 5 | B25: Sets | C25: Rep Range | D25: RPE | E25: Rest Period | F25: Load | G25: Reps | H25: MAX | I25: Load | J25: Reps | K25: MAX | L25: Load | M25: Reps | N25: MAX | O25: Volume (Load x Sets x Reps) | R25: =IF(OR(ISBLANK(N25), ISBLANK('WEEK 1'!N25)), "", ROUNDUP(N25 - 'WEEK 1'!N25, 0) & " " & IF(N25 - 'WEEK 1'!N25 > 0, "INCREASE", IF(N25 - 'WEEK 1'!N25 < 0, "DECREASE", "NO CHANGE"))) -> #VALUE!
A26: Squats leg press | B26: 3 | C26: 8–10 | E26: 60 | F26: 170 | G26: 12 | H26: =F26/(1.0278-(0.0278*G26)) -> 244.8862 | I26: 190 | J26: 13 | K26: =I26/(1.0278-(0.0278*J26)) -> 285.11405 | L26: 250 | M26: 9 | N26: =L26/(1.0278-(0.0278*M26)) -> 321.50206 | O26: =+F26*G26+I26*J26+L26*M26 -> 6760 | R26: =IF(OR(ISBLANK(N26), ISBLANK('WEEK 1'!N26)), "", ROUNDUP(N26 - 'WEEK 1'!N26, 0) & " " & IF(N26 - 'WEEK 1'!N26 > 0, "INCREASE", IF(N26 - 'WEEK 1'!N26 < 0, "DECREASE", "NO CHANGE"))) -> 223 INCREASE
A27: Barbell shrugs | B27: 3 | C27: 10–12 | E27: 60 | F27: 120 | G27: 10 | H27: =F27/(1.0278-(0.0278*G27)) -> 160.04268 | I27: 120 | J27: 10 | K27: =I27/(1.0278-(0.0278*J27)) -> 160.04268 | L27: 120 | M27: 10 | N27: =L27/(1.0278-(0.0278*M27)) -> 160.04268 | O27: =+F27*G27+I27*J27+L27*M27 -> 3600 | R27: =IF(OR(ISBLANK(N27), ISBLANK('WEEK 1'!N27)), "", ROUNDUP(N27 - 'WEEK 1'!N27, 0) & " " & IF(N27 - 'WEEK 1'!N27 > 0, "INCREASE", IF(N27 - 'WEEK 1'!N27 < 0, "DECREASE", "NO CHANGE"))) -> -34 DECREASE
A28: Roman chair | B28: 3 | C28: 12–15 | E28: 60 | F28: 0 | G28: 10 | H28: =F28/(1.0278-(0.0278*G28)) -> 0 | I28: 35 | J28: 10 | K28: =I28/(1.0278-(0.0278*J28)) -> 46.679114 | L28: 35 | M28: 10 | N28: =L28/(1.0278-(0.0278*M28)) -> 46.679114 | O28: =+F28*G28+I28*J28+L28*M28 -> 700 | R28: =IF(OR(ISBLANK(N28), ISBLANK('WEEK 1'!N28)), "", ROUNDUP(N28 - 'WEEK 1'!N28, 0) & " " & IF(N28 - 'WEEK 1'!N28 > 0, "INCREASE", IF(N28 - 'WEEK 1'!N28 < 0, "DECREASE", "NO CHANGE"))) -> 11 INCREASE
A29: Leg Curl Machine | B29: 3 | C29: 10–12 | E29: 60 | F29: 160 | G29: 10 | H29: =F29/(1.0278-(0.0278*G29)) -> 213.39024 | I29: 160 | J29: 8 | K29: =I29/(1.0278-(0.0278*J29)) -> 198.65905 | L29: 160 | M29: 10 | N29: =L29/(1.0278-(0.0278*M29)) -> 213.39024 | O29: =+F29*G29+I29*J29+L29*M29 -> 4480 | R29: =IF(OR(ISBLANK(N29), ISBLANK('WEEK 1'!N29)), "", ROUNDUP(N29 - 'WEEK 1'!N29, 0) & " " & IF(N29 - 'WEEK 1'!N29 > 0, "INCREASE", IF(N29 - 'WEEK 1'!N29 < 0, "DECREASE", "NO CHANGE"))) -> 8 INCREASE
A30: Hip Abduction | B30: 3 | C30: 10–12 | E30: 60 | F30: 250 | G30: 12 | H30: =F30/(1.0278-(0.0278*G30)) -> 360.12676 | I30: 250 | J30: 12 | K30: =I30/(1.0278-(0.0278*J30)) -> 360.12676 | L30: 250 | M30: 10 | N30: =L30/(1.0278-(0.0278*M30)) -> 333.42225 | O30: =+F30*G30+I30*J30+L30*M30 -> 8500 | R30: =IF(OR(ISBLANK(N30), ISBLANK('WEEK 1'!N30)), "", ROUNDUP(N30 - 'WEEK 1'!N30, 0) & " " & IF(N30 - 'WEEK 1'!N30 > 0, "INCREASE", IF(N30 - 'WEEK 1'!N30 < 0, "DECREASE", "NO CHANGE"))) -> 17 INCREASE
A31: Ab Oblique Crunch Machine | B31: 3 | C31: 10–12 | E31: 60 | F31: 10 | G31: 10 | H31: =F31/(1.0278-(0.0278*G31)) -> 13.33689 | I31: 10 | J31: 10 | K31: =I31/(1.0278-(0.0278*J31)) -> 13.33689 | L31: 10 | M31: 10 | N31: =L31/(1.0278-(0.0278*M31)) -> 13.33689 | O31: =+F31*G31+I31*J31+L31*M31 -> 300 | R31: =IF(OR(ISBLANK(N31), ISBLANK('WEEK 1'!N31)), "", ROUNDUP(N31 - 'WEEK 1'!N31, 0) & " " & IF(N31 - 'WEEK 1'!N31 > 0, "INCREASE", IF(N31 - 'WEEK 1'!N31 < 0, "DECREASE", "NO CHANGE"))) -> -410 DECREASE

Sheet WEEK 3
A1: Days | B1: Set 1 | E1: Set 2 | H1: Set 3 | K1: Volume | N1: MAX Difference
A2: Day 1 | B2: Load | C2: Reps | D2: MAX | E2: Load | F2: Reps | G2: MAX | H2: Load | I2: Reps | J2: MAX | K2: Volume | N2: MAX Difference
A3: Seated Chest Press Machine | B3: 160 | C3: 9 | D3: =B3/(1.0278-(0.0278*C3)) -> 205.76132 | E3: 160 | F3: 7 | G3: =E3/(1.0278-(0.0278*F3)) -> 192.03072 | H3: 160 | I3: 8 | J3: =H3/(1.0278-(0.0278*I3)) -> 198.65905 | K3: =+B3*C3+E3*F3+H3*I3 -> 3840 | N3: =IF(OR(ISBLANK(D3), ISBLANK(G3), ISBLANK(J3), ISBLANK('WEEK 2'!N4)), "", ROUNDUP((((D3 + G3 + J3) / 3) - 'WEEK 2'!N4) / 'WEEK 2'!N4 * 100, 0) & "% " & IF(((D3 + G3 + J3) / 3) - 'WEEK 2'!N4 > 0, "INCREASE", IF(((D3 + G3 + J3) / 3) - 'WEEK 2'!N4 < 0, "DECREASE", "NO CHANGE"))) -> 7% INCREASE
A4: Tricep Cable Pushdown | B4: 50 | C4: 11 | D4: =B4/(1.0278-(0.0278*C4)) -> 69.252078 | E4: 50 | F4: 11 | G4: =E4/(1.0278-(0.0278*F4)) -> 69.252078 | H4: 57.5 | I4: 8 | J4: =H4/(1.0278-(0.0278*I4)) -> 71.393097 | K4: =+B4*C4+E4*F4+H4*I4 -> 1560 | N4: =IF(OR(ISBLANK(D4), ISBLANK(G4), ISBLANK(J4), ISBLANK('WEEK 2'!N5)), "", ROUNDUP((((D4 + G4 + J4) / 3) - 'WEEK 2'!N5) / 'WEEK 2'!N5 * 100, 0) & "% " & IF(((D4 + G4 + J4) / 3) - 'WEEK 2'!N5 > 0, "INCREASE", IF(((D4 + G4 + J4) / 3) - 'WEEK 2'!N5 < 0, "DECREASE", "NO CHANGE"))) -> 19% INCREASE
A5: Seated Shoulder Press | B5: 60 | C5: 11 | D5: =B5/(1.0278-(0.0278*C5)) -> 83.102493 | E5: 60 | F5: 9 | G5: =E5/(1.0278-(0.0278*F5)) -> 77.160494 | H5: 60 | I5: 12 | J5: =H5/(1.0278-(0.0278*I5)) -> 86.430424 | K5: =+B5*C5+E5*F5+H5*I5 -> 1920 | N5: =IF(OR(ISBLANK(D5), ISBLANK(G5), ISBLANK(J5), ISBLANK('WEEK 2'!N6)), "", ROUNDUP((((D5 + G5 + J5) / 3) - 'WEEK 2'!N6) / 'WEEK 2'!N6 * 100, 0) & "% " & IF(((D5 + G5 + J5) / 3) - 'WEEK 2'!N6 > 0, "INCREASE", IF(((D5 + G5 + J5) / 3) - 'WEEK 2'!N6 < 0, "DECREASE", "NO CHANGE"))) -> 6% INCREASE
A6: Dumbbell Side Lateral Raise | B6: 15 | C6: 12 | D6: =B6/(1.0278-(0.0278*C6)) -> 21.607606 | E6: 15 | F6: 9 | G6: =E6/(1.0278-(0.0278*F6)) -> 19.290123 | H6: 15 | I6: 9 | J6: =H6/(1.0278-(0.0278*I6)) -> 19.290123 | K6: =+B6*C6+E6*F6+H6*I6 -> 450 | N6: =IF(OR(ISBLANK(D6), ISBLANK(G6), ISBLANK(J6), ISBLANK('WEEK 2'!N7)), "", ROUNDUP((((D6 + G6 + J6) / 3) - 'WEEK 2'!N7) / 'WEEK 2'!N7 * 100, 0) & "% " & IF(((D6 + G6 + J6) / 3) - 'WEEK 2'!N7 > 0, "INCREASE", IF(((D6 + G6 + J6) / 3) - 'WEEK 2'!N7 < 0, "DECREASE", "NO CHANGE"))) -> 1% INCREASE
A7: Pectoral Fly | B7: 150 | C7: 8 | D7: =B7/(1.0278-(0.0278*C7)) -> 186.24286 | E7: 145 | F7: 9 | G7: =E7/(1.0278-(0.0278*F7)) -> 186.47119 | H7: 145 | I7: 8 | J7: =H7/(1.0278-(0.0278*I7)) -> 180.03477 | K7: =+B7*C7+E7*F7+H7*I7 -> 3665 | N7: =IF(OR(ISBLANK(D7), ISBLANK(G7), ISBLANK(J7), ISBLANK('WEEK 2'!N8)), "", ROUNDUP((((D7 + G7 + J7) / 3) - 'WEEK 2'!N8) / 'WEEK 2'!N8 * 100, 0) & "% " & IF(((D7 + G7 + J7) / 3) - 'WEEK 2'!N8 > 0, "INCREASE", IF(((D7 + G7 + J7) / 3) - 'WEEK 2'!N8 < 0, "DECREASE", "NO CHANGE"))) -> 3% INCREASE
A8: Ab Twist Machine | B8: 145 | C8: 12 | D8: =B8/(1.0278-(0.0278*C8)) -> 208.87352 | E8: 145 | F8: 11 | G8: =E8/(1.0278-(0.0278*F8)) -> 200.83102 | H8: 145 | I8: 11 | J8: =H8/(1.0278-(0.0278*I8)) -> 200.83102 | K8: =+B8*C8+E8*F8+H8*I8 -> 4930 | N8: =IF(OR(ISBLANK(D8), ISBLANK(G8), ISBLANK(J8), ISBLANK('WEEK 2'!N9)), "", ROUNDUP((((D8 + G8 + J8) / 3) - 'WEEK 2'!N9) / 'WEEK 2'!N9 * 100, 0) & "% " & IF(((D8 + G8 + J8) / 3) - 'WEEK 2'!N9 > 0, "INCREASE", IF(((D8 + G8 + J8) / 3) - 'WEEK 2'!N9 < 0, "DECREASE", "NO CHANGE"))) -> 2% INCREASE
A9: Day 2 | B9: Load | C9: Reps | D9: MAX | E9: Load | F9: Reps | G9: MAX | H9: Load | I9: Reps | J9: MAX | K9: Volume | N9: MAX Difference
A10: Row Machine | D10: =B10/(1.0278-(0.0278*C10)) -> 0 | G10: =E10/(1.0278-(0.0278*F10)) -> 0 | J10: =H10/(1.0278-(0.0278*I10)) -> 0 | K10: =+B10*C10+E10*F10+H10*I10 -> 0 | N10: =IF(OR(ISBLANK(D10), ISBLANK(G10), ISBLANK(J10), ISBLANK('WEEK 2'!N11)), "", ROUNDUP((((D10 + G10 + J10) / 3) - 'WEEK 2'!N11) / 'WEEK 2'!N11 * 100, 0) & "% " & IF(((D10 + G10 + J10) / 3) - 'WEEK 2'!N11 > 0, "INCREASE", IF(((D10 + G10 + J10) / 3) - 'WEEK 2'!N11 < 0, "DECREASE", "NO CHANGE"))) -> -100% DECREASE
A11: Wide Grip Pull-Up (Assisted) | D11: =B11/(1.0278-(0.0278*C11)) -> 0 | G11: =E11/(1.0278-(0.0278*F11)) -> 0 | J11: =H11/(1.0278-(0.0278*I11)) -> 0 | K11: =+B11*C11+E11*F11+H11*I11 -> 0 | N11: =IF(OR(ISBLANK(D11), ISBLANK(G11), ISBLANK(J11), ISBLANK('WEEK 2'!N12)), "", ROUNDUP((((D11 + G11 + J11) / 3) - 'WEEK 2'!N12) / 'WEEK 2'!N12 * 100, 0) & "% " & IF(((D11 + G11 + J11) / 3) - 'WEEK 2'!N12 > 0, "INCREASE", IF(((D11 + G11 + J11) / 3) - 'WEEK 2'!N12 < 0, "DECREASE", "NO CHANGE"))) -> #DIV/0!
A12: Preacher Curl | D12: =B12/(1.0278-(0.0278*C12)) -> 0 | G12: =E12/(1.0278-(0.0278*F12)) -> 0 | J12: =H12/(1.0278-(0.0278*I12)) -> 0 | K12: =+B12*C12+E12*F12+H12*I12 -> 0 | N12: =IF(OR(ISBLANK(D12), ISBLANK(G12), ISBLANK(J12), ISBLANK('WEEK 2'!N13)), "", ROUNDUP((((D12 + G12 + J12) / 3) - 'WEEK 2'!N13) / 'WEEK 2'!N13 * 100, 0) & "% " & IF(((D12 + G12 + J12) / 3) - 'WEEK 2'!N13 > 0, "INCREASE", IF(((D12 + G12 + J12) / 3) - 'WEEK 2'!N13 < 0, "DECREASE", "NO CHANGE"))) -> -100% DECREASE
A13: Lat Pulldown | D13: =B13/(1.0278-(0.0278*C13)) -> 0 | G13: =E13/(1.0278-(0.0278*F13)) -> 0 | J13: =H13/(1.0278-(0.0278*I13)) -> 0 | K13: =+B13*C13+E13*F13+H13*I13 -> 0 | N13: =IF(OR(ISBLANK(D13), ISBLANK(G13), ISBLANK(J13), ISBLANK('WEEK 2'!N14)), "", ROUNDUP((((D13 + G13 + J13) / 3) - 'WEEK 2'!N14) / 'WEEK 2'!N14 * 100, 0) & "% " & IF(((D13 + G13 + J13) / 3) - 'WEEK 2'!N14 > 0, "INCREASE", IF(((D13 + G13 + J13) / 3) - 'WEEK 2'!N14 < 0, "DECREASE", "NO CHANGE"))) -> #DIV/0!
A14: Dumbbell Shrugs | D14: =B14/(1.0278-(0.0278*C14)) -> 0 | G14: =E14/(1.0278-(0.0278*F14)) -> 0 | J14: =H14/(1.0278-(0.0278*I14)) -> 0 | K14: =+B14*C14+E14*F14+H14*I14 -> 0 | N14: =IF(OR(ISBLANK(D14), ISBLANK(G14), ISBLANK(J14), ISBLANK('WEEK 2'!N15)), "", ROUNDUP((((D14 + G14 + J14) / 3) - 'WEEK 2'!N15) / 'WEEK 2'!N15 * 100, 0) & "% " & IF(((D14 + G14 + J14) / 3) - 'WEEK 2'!N15 > 0, "INCREASE", IF(((D14 + G14 + J14) / 3) - 'WEEK 2'!N15 < 0, "DECREASE", "NO CHANGE"))) -> -100% DECREASE
A15: Cable Ab Curl | D15: =B15/(1.0278-(0.0278*C15)) -> 0 | G15: =E15/(1.0278-(0.0278*F15)) -> 0 | J15: =H15/(1.0278-(0.0278*I15)) -> 0 | K15: =+B15*C15+E15*F15+H15*I15 -> 0 | N15: =IF(OR(ISBLANK(D15), ISBLANK(G15), ISBLANK(J15), ISBLANK('WEEK 2'!N16)), "", ROUNDUP((((D15 + G15 + J15) / 3) - 'WEEK 2'!N16) / 'WEEK 2'!N16 * 100, 0) & "% " & IF(((D15 + G15 + J15) / 3) - 'WEEK 2'!N16 > 0, "INCREASE", IF(((D15 + G15 + J15) / 3) - 'WEEK 2'!N16 < 0, "DECREASE", "NO CHANGE"))) -> -100% DECREASE
A16: Day 4 | B16: Load | C16: Reps | D16: MAX | E16: Load | F16: Reps | G16: MAX | H16: Load | I16: Reps | J16: MAX | K16: Volume | N16: MAX Difference
A17: Chest Press Machine | D17: =B17/(1.0278-(0.0278*C17)) -> 0 | G17: =E17/(1.0278-(0.0278*F17)) -> 0 | J17: =H17/(1.0278-(0.0278*I17)) -> 0 | K17: =+B17*C17+E17*F17+H17*I17 -> 0 | N17: =IF(OR(ISBLANK(D17), ISBLANK(G17), ISBLANK(J17), ISBLANK('WEEK 2'!N18)), "", ROUNDUP((((D17 + G17 + J17) / 3) - 'WEEK 2'!N18) / 'WEEK 2'!N18 * 100, 0) & "% " & IF(((D17 + G17 + J17) / 3) - 'WEEK 2'!N18 > 0, "INCREASE", IF(((D17 + G17 + J17) / 3) - 'WEEK 2'!N18 < 0, "DECREASE", "NO CHANGE"))) -> #DIV/0!
A18: Wide Grip Pull-Up (Assisted) | D18: =B18/(1.0278-(0.0278*C18)) -> 0 | G18: =E18/(1.0278-(0.0278*F18)) -> 0 | J18: =H18/(1.0278-(0.0278*I18)) -> 0 | K18: =+B18*C18+E18*F18+H18*I18 -> 0 | N18: =IF(OR(ISBLANK(D18), ISBLANK(G18), ISBLANK(J18), ISBLANK('WEEK 2'!N19)), "", ROUNDUP((((D18 + G18 + J18) / 3) - 'WEEK 2'!N19) / 'WEEK 2'!N19 * 100, 0) & "% " & IF(((D18 + G18 + J18) / 3) - 'WEEK 2'!N19 > 0, "INCREASE", IF(((D18 + G18 + J18) / 3) - 'WEEK 2'!N19 < 0, "DECREASE", "NO CHANGE"))) -> #VALUE!
A19: Neck Flexion | D19: =B19/(1.0278-(0.0278*C19)) -> 0 | G19: =E19/(1.0278-(0.0278*F19)) -> 0 | J19: =H19/(1.0278-(0.0278*I19)) -> 0 | K19: =+B19*C19+E19*F19+H19*I19 -> 0 | N19: =IF(OR(ISBLANK(D19), ISBLANK(G19), ISBLANK(J19), ISBLANK('WEEK 2'!N20)), "", ROUNDUP((((D19 + G19 + J19) / 3) - 'WEEK 2'!N20) / 'WEEK 2'!N20 * 100, 0) & "% " & IF(((D19 + G19 + J19) / 3) - 'WEEK 2'!N20 > 0, "INCREASE", IF(((D19 + G19 + J19) / 3) - 'WEEK 2'!N20 < 0, "DECREASE", "NO CHANGE"))) -> #DIV/0!
A20: Tricep Dips (Assisted) | D20: =B20/(1.0278-(0.0278*C20)) -> 0 | G20: =E20/(1.0278-(0.0278*F20)) -> 0 | J20: =H20/(1.0278-(0.0278*I20)) -> 0 | K20: =+B20*C20+E20*F20+H20*I20 -> 0 | N20: =IF(OR(ISBLANK(D20), ISBLANK(G20), ISBLANK(J20), ISBLANK('WEEK 2'!N21)), "", ROUNDUP((((D20 + G20 + J20) / 3) - 'WEEK 2'!N21) / 'WEEK 2'!N21 * 100, 0) & "% " & IF(((D20 + G20 + J20) / 3) - 'WEEK 2'!N21 > 0, "INCREASE", IF(((D20 + G20 + J20) / 3) - 'WEEK 2'!N21 < 0, "DECREASE", "NO CHANGE"))) -> #DIV/0!
A21: Preacher Curl | D21: =B21/(1.0278-(0.0278*C21)) -> 0 | G21: =E21/(1.0278-(0.0278*F21)) -> 0 | J21: =H21/(1.0278-(0.0278*I21)) -> 0 | K21: =+B21*C21+E21*F21+H21*I21 -> 0 | N21: =IF(OR(ISBLANK(D21), ISBLANK(G21), ISBLANK(J21), ISBLANK('WEEK 2'!N22)), "", ROUNDUP((((D21 + G21 + J21) / 3) - 'WEEK 2'!N22) / 'WEEK 2'!N22 * 100, 0) & "% " & IF(((D21 + G21 + J21) / 3) - 'WEEK 2'!N22 > 0, "INCREASE", IF(((D21 + G21 + J21) / 3) - 'WEEK 2'!N22 < 0, "DECREASE", "NO CHANGE"))) -> #DIV/0!
A22: Day 5 | B22: Load | C22: Reps | D22: MAX | E22: Load | F22: Reps | G22: MAX | H22: Load | I22: Reps | J22: MAX | K22: Volume | N22: MAX Difference
A23: Squats Leg Press | D23: =B23/(1.0278-(0.0278*C23)) -> 0 | G23: =E23/(1.0278-(0.0278*F23)) -> 0 | J23: =H23/(1.0278-(0.0278*I23)) -> 0 | K23: =+B23*C23+E23*F23+H23*I23 -> 0 | N23: =IF(OR(ISBLANK(D23), ISBLANK(G23), ISBLANK(J23), ISBLANK('WEEK 2'!N24)), "", ROUNDUP((((D23 + G23 + J23) / 3) - 'WEEK 2'!N24) / 'WEEK 2'!N24 * 100, 0) & "% " & IF(((D23 + G23 + J23) / 3) - 'WEEK 2'!N24 > 0, "INCREASE", IF(((D23 + G23 + J23) / 3) - 'WEEK 2'!N24 < 0, "DECREASE", "NO CHANGE"))) -> #DIV/0!
A24: Dumbbell Shrugs | D24: =B24/(1.0278-(0.0278*C24)) -> 0 | G24: =E24/(1.0278-(0.0278*F24)) -> 0 | J24: =H24/(1.0278-(0.0278*I24)) -> 0 | K24: =+B24*C24+E24*F24+H24*I24 -> 0 | N24: =IF(OR(ISBLANK(D24), ISBLANK(G24), ISBLANK(J24), ISBLANK('WEEK 2'!N25)), "", ROUNDUP((((D24 + G24 + J24) / 3) - 'WEEK 2'!N25) / 'WEEK 2'!N25 * 100, 0) & "% " & IF(((D24 + G24 + J24) / 3) - 'WEEK 2'!N25 > 0, "INCREASE", IF(((D24 + G24 + J24) / 3) - 'WEEK 2'!N25 < 0, "DECREASE", "NO CHANGE"))) -> #VALUE!
A25: Roman Chair | D25: =B25/(1.0278-(0.0278*C25)) -> 0 | G25: =E25/(1.0278-(0.0278*F25)) -> 0 | J25: =H25/(1.0278-(0.0278*I25)) -> 0 | K25: =+B25*C25+E25*F25+H25*I25 -> 0 | N25: =IF(OR(ISBLANK(D25), ISBLANK(G25), ISBLANK(J25), ISBLANK('WEEK 2'!N26)), "", ROUNDUP((((D25 + G25 + J25) / 3) - 'WEEK 2'!N26) / 'WEEK 2'!N26 * 100, 0) & "% " & IF(((D25 + G25 + J25) / 3) - 'WEEK 2'!N26 > 0, "INCREASE", IF(((D25 + G25 + J25) / 3) - 'WEEK 2'!N26 < 0, "DECREASE", "NO CHANGE"))) -> -100% DECREASE
A26: Leg Curl Machine | D26: =B26/(1.0278-(0.0278*C26)) -> 0 | G26: =E26/(1.0278-(0.0278*F26)) -> 0 | J26: =H26/(1.0278-(0.0278*I26)) -> 0 | K26: =+B26*C26+E26*F26+H26*I26 -> 0 | N26: =IF(OR(ISBLANK(D26), ISBLANK(G26), ISBLANK(J26), ISBLANK('WEEK 2'!N27)), "", ROUNDUP((((D26 + G26 + J26) / 3) - 'WEEK 2'!N27) / 'WEEK 2'!N27 * 100, 0) & "% " & IF(((D26 + G26 + J26) / 3) - 'WEEK 2'!N27 > 0, "INCREASE", IF(((D26 + G26 + J26) / 3) - 'WEEK 2'!N27 < 0, "DECREASE", "NO CHANGE"))) -> -100% DECREASE
A27: Hip Abduction | D27: =B27/(1.0278-(0.0278*C27)) -> 0 | G27: =E27/(1.0278-(0.0278*F27)) -> 0 | J27: =H27/(1.0278-(0.0278*I27)) -> 0 | K27: =+B27*C27+E27*F27+H27*I27 -> 0 | N27: =IF(OR(ISBLANK(D27), ISBLANK(G27), ISBLANK(J27), ISBLANK('WEEK 2'!N28)), "", ROUNDUP((((D27 + G27 + J27) / 3) - 'WEEK 2'!N28) / 'WEEK 2'!N28 * 100, 0) & "% " & IF(((D27 + G27 + J27) / 3) - 'WEEK 2'!N28 > 0, "INCREASE", IF(((D27 + G27 + J27) / 3) - 'WEEK 2'!N28 < 0, "DECREASE", "NO CHANGE"))) -> -100% DECREASE
A28: Ab Oblique Crunch Machine | D28: =B28/(1.0278-(0.0278*C28)) -> 0 | G28: =E28/(1.0278-(0.0278*F28)) -> 0 | J28: =H28/(1.0278-(0.0278*I28)) -> 0 | K28: =+B28*C28+E28*F28+H28*I28 -> 0 | N28: =IF(OR(ISBLANK(D28), ISBLANK(G28), ISBLANK(J28), ISBLANK('WEEK 2'!N29)), "", ROUNDUP((((D28 + G28 + J28) / 3) - 'WEEK 2'!N29) / 'WEEK 2'!N29 * 100, 0) & "% " & IF(((D28 + G28 + J28) / 3) - 'WEEK 2'!N29 > 0, "INCREASE", IF(((D28 + G28 + J28) / 3) - 'WEEK 2'!N29 < 0, "DECREASE", "NO CHANGE"))) -> -100% DECREASE

Sheet Week 4
A1: Days | B1: Set 1 | E1: Set 2 | H1: Set 3 | K1: Volume | N1: MAX Difference
A2: Day 1 | B2: Load | C2: Reps | D2: MAX | E2: Load | F2: Reps | G2: MAX | H2: Load | I2: Reps | J2: MAX | K2: Volume | N2: MAX Difference
A3: Seated Chest Press Machine | B3: 160 | C3: 12 | D3: =B3/(1.0278-(0.0278*C3)) -> 230.48113 | E3: 160 | F3: 11 | G3: =E3/(1.0278-(0.0278*F3)) -> 221.60665 | H3: 160 | I3: 9 | J3: =H3/(1.0278-(0.0278*I3)) -> 205.76132 | K3: =+B3*C3+E3*F3+H3*I3 -> 5120 | N3: =IF(OR(ISBLANK(D3), ISBLANK(G3), ISBLANK(J3), ISBLANK('WEEK 2'!N4)), "", ROUNDUP((((D3 + G3 + J3) / 3) - 'WEEK 2'!N4) / 'WEEK 2'!N4 * 100, 0) & "% " & IF(((D3 + G3 + J3) / 3) - 'WEEK 2'!N4 > 0, "INCREASE", IF(((D3 + G3 + J3) / 3) - 'WEEK 2'!N4 < 0, "DECREASE", "NO CHANGE"))) -> 19% INCREASE
A4: Tricep Cable Pushdown | B4: 50 | C4: 14 | D4: =B4/(1.0278-(0.0278*C4)) -> 78.296273 | E4: 57.5 | F4: 8 | G4: =E4/(1.0278-(0.0278*F4)) -> 71.393097 | H4: 52.5 | I4: 10 | J4: =H4/(1.0278-(0.0278*I4)) -> 70.018672 | K4: =+B4*C4+E4*F4+H4*I4 -> 1685 | N4: =IF(OR(ISBLANK(D4), ISBLANK(G4), ISBLANK(J4), ISBLANK('WEEK 2'!N5)), "", ROUNDUP((((D4 + G4 + J4) / 3) - 'WEEK 2'!N5) / 'WEEK 2'!N5 * 100, 0) & "% " & IF(((D4 + G4 + J4) / 3) - 'WEEK 2'!N5 > 0, "INCREASE", IF(((D4 + G4 + J4) / 3) - 'WEEK 2'!N5 < 0, "DECREASE", "NO CHANGE"))) -> 25% INCREASE
A5: Seated Shoulder Press | B5: 60 | C5: 12 | D5: =B5/(1.0278-(0.0278*C5)) -> 86.430424 | E5: 60 | F5: 10 | G5: =E5/(1.0278-(0.0278*F5)) -> 80.021339 | H5: 60 | I5: 10 | J5: =H5/(1.0278-(0.0278*I5)) -> 80.021339 | K5: =+B5*C5+E5*F5+H5*I5 -> 1920 | N5: =IF(OR(ISBLANK(D5), ISBLANK(G5), ISBLANK(J5), ISBLANK('WEEK 2'!N6)), "", ROUNDUP((((D5 + G5 + J5) / 3) - 'WEEK 2'!N6) / 'WEEK 2'!N6 * 100, 0) & "% " & IF(((D5 + G5 + J5) / 3) - 'WEEK 2'!N6 > 0, "INCREASE", IF(((D5 + G5 + J5) / 3) - 'WEEK 2'!N6 < 0, "DECREASE", "NO CHANGE"))) -> 6% INCREASE
A6: Dumbbell Side Lateral Raise | B6: 15 | C6: 12 | D6: =B6/(1.0278-(0.0278*C6)) -> 21.607606 | E6: 20 | F6: 10 | G6: =E6/(1.0278-(0.0278*F6)) -> 26.67378 | H6: 20 | I6: 10 | J6: =H6/(1.0278-(0.0278*I6)) -> 26.67378 | K6: =+B6*C6+E6*F6+H6*I6 -> 580 | N6: =IF(OR(ISBLANK(D6), ISBLANK(G6), ISBLANK(J6), ISBLANK('WEEK 2'!N7)), "", ROUNDUP((((D6 + G6 + J6) / 3) - 'WEEK 2'!N7) / 'WEEK 2'!N7 * 100, 0) & "% " & IF(((D6 + G6 + J6) / 3) - 'WEEK 2'!N7 > 0, "INCREASE", IF(((D6 + G6 + J6) / 3) - 'WEEK 2'!N7 < 0, "DECREASE", "NO CHANGE"))) -> 25% INCREASE
A7: Pectoral Fly | B7: 150 | C7: 8 | D7: =B7/(1.0278-(0.0278*C7)) -> 186.24286 | E7: 145 | F7: 9 | G7: =E7/(1.0278-(0.0278*F7)) -> 186.47119 | H7: 145 | I7: 8 | J7: =H7/(1.0278-(0.0278*I7)) -> 180.03477 | K7: =+B7*C7+E7*F7+H7*I7 -> 3665 | N7: =IF(OR(ISBLANK(D7), ISBLANK(G7), ISBLANK(J7), ISBLANK('WEEK 2'!N8)), "", ROUNDUP((((D7 + G7 + J7) / 3) - 'WEEK 2'!N8) / 'WEEK 2'!N8 * 100, 0) & "% " & IF(((D7 + G7 + J7) / 3) - 'WEEK 2'!N8 > 0, "INCREASE", IF(((D7 + G7 + J7) / 3) - 'WEEK 2'!N8 < 0, "DECREASE", "NO CHANGE"))) -> 3% INCREASE
A8: Ab Twist Machine | B8: 145 | C8: 12 | D8: =B8/(1.0278-(0.0278*C8)) -> 208.87352 | E8: 145 | F8: 11 | G8: =E8/(1.0278-(0.0278*F8)) -> 200.83102 | H8: 145 | I8: 11 | J8: =H8/(1.0278-(0.0278*I8)) -> 200.83102 | K8: =+B8*C8+E8*F8+H8*I8 -> 4930 | N8: =IF(OR(ISBLANK(D8), ISBLANK(G8), ISBLANK(J8), ISBLANK('WEEK 2'!N9)), "", ROUNDUP((((D8 + G8 + J8) / 3) - 'WEEK 2'!N9) / 'WEEK 2'!N9 * 100, 0) & "% " & IF(((D8 + G8 + J8) / 3) - 'WEEK 2'!N9 > 0, "INCREASE", IF(((D8 + G8 + J8) / 3) - 'WEEK 2'!N9 < 0, "DECREASE", "NO CHANGE"))) -> 2% INCREASE
A9: Day 2 | B9: Load | C9: Reps | D9: MAX | E9: Load | F9: Reps | G9: MAX | H9: Load | I9: Reps | J9: MAX | K9: Volume | N9: MAX Difference
A10: Row Machine | B10: 190 | C10: 8 | D10: =B10/(1.0278-(0.0278*C10)) -> 235.90762 | E10: 175 | F10: 9 | G10: =E10/(1.0278-(0.0278*F10)) -> 225.05144 | H10: 175 | I10: 8 | J10: =H10/(1.0278-(0.0278*I10)) -> 217.28334 | K10: =+B10*C10+E10*F10+H10*I10 -> 4495 | N10: =IF(OR(ISBLANK(D10), ISBLANK(G10), ISBLANK(J10), ISBLANK('WEEK 2'!N11)), "", ROUNDUP((((D10 + G10 + J10) / 3) - 'WEEK 2'!N11) / 'WEEK 2'!N11 * 100, 0) & "% " & IF(((D10 + G10 + J10) / 3) - 'WEEK 2'!N11 > 0, "INCREASE", IF(((D10 + G10 + J10) / 3) - 'WEEK 2'!N11 < 0, "DECREASE", "NO CHANGE"))) -> -2% DECREASE
A11: Wide Grip Pull-Up (Assisted) | B11: 40 | C11: 8 | D11: =B11/(1.0278-(0.0278*C11)) -> 49.664763 | E11: 40 | F11: 7 | G11: =E11/(1.0278-(0.0278*F11)) -> 48.007681 | H11: 40 | I11: 5 | J11: =H11/(1.0278-(0.0278*I11)) -> 45.0045 | K11: =+B11*C11+E11*F11+H11*I11 -> 800 | N11: =IF(OR(ISBLANK(D11), ISBLANK(G11), ISBLANK(J11), ISBLANK('WEEK 2'!N12)), "", ROUNDUP((((D11 + G11 + J11) / 3) - 'WEEK 2'!N12) / 'WEEK 2'!N12 * 100, 0) & "% " & IF(((D11 + G11 + J11) / 3) - 'WEEK 2'!N12 > 0, "INCREASE", IF(((D11 + G11 + J11) / 3) - 'WEEK 2'!N12 < 0, "DECREASE", "NO CHANGE"))) -> #DIV/0!
A12: Preacher Curl | B12: 125 | C12: 10 | D12: =B12/(1.0278-(0.0278*C12)) -> 166.71112 | E12: 125 | F12: 8 | G12: =E12/(1.0278-(0.0278*F12)) -> 155.20238 | H12: 110 | I12: 10 | J12: =H12/(1.0278-(0.0278*I12)) -> 146.70579 | K12: =+B12*C12+E12*F12+H12*I12 -> 3350 | N12: =IF(OR(ISBLANK(D12), ISBLANK(G12), ISBLANK(J12), ISBLANK('WEEK 2'!N13)), "", ROUNDUP((((D12 + G12 + J12) / 3) - 'WEEK 2'!N13) / 'WEEK 2'!N13 * 100, 0) & "% " & IF(((D12 + G12 + J12) / 3) - 'WEEK 2'!N13 > 0, "INCREASE", IF(((D12 + G12 + J12) / 3) - 'WEEK 2'!N13 < 0, "DECREASE", "NO CHANGE"))) -> 5% INCREASE
A13: Lat Pulldown | D13: =B13/(1.0278-(0.0278*C13)) -> 0 | G13: =E13/(1.0278-(0.0278*F13)) -> 0 | J13: =H13/(1.0278-(0.0278*I13)) -> 0 | K13: =+B13*C13+E13*F13+H13*I13 -> 0 | N13: =IF(OR(ISBLANK(D13), ISBLANK(G13), ISBLANK(J13), ISBLANK('WEEK 2'!N14)), "", ROUNDUP((((D13 + G13 + J13) / 3) - 'WEEK 2'!N14) / 'WEEK 2'!N14 * 100, 0) & "% " & IF(((D13 + G13 + J13) / 3) - 'WEEK 2'!N14 > 0, "INCREASE", IF(((D13 + G13 + J13) / 3) - 'WEEK 2'!N14 < 0, "DECREASE", "NO CHANGE"))) -> #DIV/0!
A14: Dumbbell Shrugs | B14: 120 | C14: 14 | D14: =B14/(1.0278-(0.0278*C14)) -> 187.91106 | E14: 120 | F14: 12 | G14: =E14/(1.0278-(0.0278*F14)) -> 172.86085 | H14: 120 | I14: 12 | J14: =H14/(1.0278-(0.0278*I14)) -> 172.86085 | K14: =+B14*C14+E14*F14+H14*I14 -> 4560 | N14: =IF(OR(ISBLANK(D14), ISBLANK(G14), ISBLANK(J14), ISBLANK('WEEK 2'!N15)), "", ROUNDUP((((D14 + G14 + J14) / 3) - 'WEEK 2'!N15) / 'WEEK 2'!N15 * 100, 0) & "% " & IF(((D14 + G14 + J14) / 3) - 'WEEK 2'!N15 > 0, "INCREASE", IF(((D14 + G14 + J14) / 3) - 'WEEK 2'!N15 < 0, "DECREASE", "NO CHANGE"))) -> 8% INCREASE
A15: Cable Ab Curl | B15: 77.5 | C15: 12 | D15: =B15/(1.0278-(0.0278*C15)) -> 111.6393 | E15: 77.5 | F15: 12 | G15: =E15/(1.0278-(0.0278*F15)) -> 111.6393 | H15: 77.5 | I15: 12 | J15: =H15/(1.0278-(0.0278*I15)) -> 111.6393 | K15: =+B15*C15+E15*F15+H15*I15 -> 2790 | N15: =IF(OR(ISBLANK(D15), ISBLANK(G15), ISBLANK(J15), ISBLANK('WEEK 2'!N16)), "", ROUNDUP((((D15 + G15 + J15) / 3) - 'WEEK 2'!N16) / 'WEEK 2'!N16 * 100, 0) & "% " & IF(((D15 + G15 + J15) / 3) - 'WEEK 2'!N16 > 0, "INCREASE", IF(((D15 + G15 + J15) / 3) - 'WEEK 2'!N16 < 0, "DECREASE", "NO CHANGE"))) -> -4% DECREASE
A16: Day 4 | B16: Load | C16: Reps | D16: MAX | E16: Load | F16: Reps | G16: MAX | H16: Load | I16: Reps | J16: MAX | K16: Volume | N16: MAX Difference
A17: Chest Press Machine | D17: =B17/(1.0278-(0.0278*C17)) -> 0 | G17: =E17/(1.0278-(0.0278*F17)) -> 0 | J17: =H17/(1.0278-(0.0278*I17)) -> 0 | K17: =+B17*C17+E17*F17+H17*I17 -> 0 | N17: =IF(OR(ISBLANK(D17), ISBLANK(G17), ISBLANK(J17), ISBLANK('WEEK 2'!N18)), "", ROUNDUP((((D17 + G17 + J17) / 3) - 'WEEK 2'!N18) / 'WEEK 2'!N18 * 100, 0) & "% " & IF(((D17 + G17 + J17) / 3) - 'WEEK 2'!N18 > 0, "INCREASE", IF(((D17 + G17 + J17) / 3) - 'WEEK 2'!N18 < 0, "DECREASE", "NO CHANGE"))) -> #DIV/0!
A18: Wide Grip Pull-Up (Assisted) | D18: =B18/(1.0278-(0.0278*C18)) -> 0 | G18: =E18/(1.0278-(0.0278*F18)) -> 0 | J18: =H18/(1.0278-(0.0278*I18)) -> 0 | K18: =+B18*C18+E18*F18+H18*I18 -> 0 | N18: =IF(OR(ISBLANK(D18), ISBLANK(G18), ISBLANK(J18), ISBLANK('WEEK 2'!N19)), "", ROUNDUP((((D18 + G18 + J18) / 3) - 'WEEK 2'!N19) / 'WEEK 2'!N19 * 100, 0) & "% " & IF(((D18 + G18 + J18) / 3) - 'WEEK 2'!N19 > 0, "INCREASE", IF(((D18 + G18 + J18) / 3) - 'WEEK 2'!N19 < 0, "DECREASE", "NO CHANGE"))) -> #VALUE!
A19: Neck Flexion | D19: =B19/(1.0278-(0.0278*C19)) -> 0 | G19: =E19/(1.0278-(0.0278*F19)) -> 0 | J19: =H19/(1.0278-(0.0278*I19)) -> 0 | K19: =+B19*C19+E19*F19+H19*I19 -> 0 | N19: =IF(OR(ISBLANK(D19), ISBLANK(G19), ISBLANK(J19), ISBLANK('WEEK 2'!N20)), "", ROUNDUP((((D19 + G19 + J19) / 3) - 'WEEK 2'!N20) / 'WEEK 2'!N20 * 100, 0) & "% " & IF(((D19 + G19 + J19) / 3) - 'WEEK 2'!N20 > 0, "INCREASE", IF(((D19 + G19 + J19) / 3) - 'WEEK 2'!N20 < 0, "DECREASE", "NO CHANGE"))) -> #DIV/0!
A20: Tricep Dips (Assisted) | D20: =B20/(1.0278-(0.0278*C20)) -> 0 | G20: =E20/(1.0278-(0.0278*F20)) -> 0 | J20: =H20/(1.0278-(0.0278*I20)) -> 0 | K20: =+B20*C20+E20*F20+H20*I20 -> 0 | N20: =IF(OR(ISBLANK(D20), ISBLANK(G20), ISBLANK(J20), ISBLANK('WEEK 2'!N21)), "", ROUNDUP((((D20 + G20 + J20) / 3) - 'WEEK 2'!N21) / 'WEEK 2'!N21 * 100, 0) & "% " & IF(((D20 + G20 + J20) / 3) - 'WEEK 2'!N21 > 0, "INCREASE", IF(((D20 + G20 + J20) / 3) - 'WEEK 2'!N21 < 0, "DECREASE", "NO CHANGE"))) -> #DIV/0!
A21: Preacher Curl | D21: =B21/(1.0278-(0.0278*C21)) -> 0 | G21: =E21/(1.0278-(0.0278*F21)) -> 0 | J21: =H21/(1.0278-(0.0278*I21)) -> 0 | K21: =+B21*C21+E21*F21+H21*I21 -> 0 | N21: =IF(OR(ISBLANK(D21), ISBLANK(G21), ISBLANK(J21), ISBLANK('WEEK 2'!N22)), "", ROUNDUP((((D21 + G21 + J21) / 3) - 'WEEK 2'!N22) / 'WEEK 2'!N22 * 100, 0) & "% " & IF(((D21 + G21 + J21) / 3) - 'WEEK 2'!N22 > 0, "INCREASE", IF(((D21 + G21 + J21) / 3) - 'WEEK 2'!N22 < 0, "DECREASE", "NO CHANGE"))) -> #DIV/0!
A22: Day 5 | B22: Load | C22: Reps | D22: MAX | E22: Load | F22: Reps | G22: MAX | H22: Load | I22: Reps | J22: MAX | K22: Volume | N22: MAX Difference
A23: Squats Leg Press | D23: =B23/(1.0278-(0.0278*C23)) -> 0 | G23: =E23/(1.0278-(0.0278*F23)) -> 0 | J23: =H23/(1.0278-(0.0278*I23)) -> 0 | K23: =+B23*C23+E23*F23+H23*I23 -> 0 | N23: =IF(OR(ISBLANK(D23), ISBLANK(G23), ISBLANK(J23), ISBLANK('WEEK 2'!N24)), "", ROUNDUP((((D23 + G23 + J23) / 3) - 'WEEK 2'!N24) / 'WEEK 2'!N24 * 100, 0) & "% " & IF(((D23 + G23 + J23) / 3) - 'WEEK 2'!N24 > 0, "INCREASE", IF(((D23 + G23 + J23) / 3) - 'WEEK 2'!N24 < 0, "DECREASE", "NO CHANGE"))) -> #DIV/0!
A24: Dumbbell Shrugs | D24: =B24/(1.0278-(0.0278*C24)) -> 0 | G24: =E24/(1.0278-(0.0278*F24)) -> 0 | J24: =H24/(1.0278-(0.0278*I24)) -> 0 | K24: =+B24*C24+E24*F24+H24*I24 -> 0 | N24: =IF(OR(ISBLANK(D24), ISBLANK(G24), ISBLANK(J24), ISBLANK('WEEK 2'!N25)), "", ROUNDUP((((D24 + G24 + J24) / 3) - 'WEEK 2'!N25) / 'WEEK 2'!N25 * 100, 0) & "% " & IF(((D24 + G24 + J24) / 3) - 'WEEK 2'!N25 > 0, "INCREASE", IF(((D24 + G24 + J24) / 3) - 'WEEK 2'!N25 < 0, "DECREASE", "NO CHANGE"))) -> #VALUE!
A25: Roman Chair | D25: =B25/(1.0278-(0.0278*C25)) -> 0 | G25: =E25/(1.0278-(0.0278*F25)) -> 0 | J25: =H25/(1.0278-(0.0278*I25)) -> 0 | K25: =+B25*C25+E25*F25+H25*I25 -> 0 | N25: =IF(OR(ISBLANK(D25), ISBLANK(G25), ISBLANK(J25), ISBLANK('WEEK 2'!N26)), "", ROUNDUP((((D25 + G25 + J25) / 3) - 'WEEK 2'!N26) / 'WEEK 2'!N26 * 100, 0) & "% " & IF(((D25 + G25 + J25) / 3) - 'WEEK 2'!N26 > 0, "INCREASE", IF(((D25 + G25 + J25) / 3) - 'WEEK 2'!N26 < 0, "DECREASE", "NO CHANGE"))) -> -100% DECREASE
A26: Leg Curl Machine | D26: =B26/(1.0278-(0.0278*C26)) -> 0 | G26: =E26/(1.0278-(0.0278*F26)) -> 0 | J26: =H26/(1.0278-(0.0278*I26)) -> 0 | K26: =+B26*C26+E26*F26+H26*I26 -> 0 | N26: =IF(OR(ISBLANK(D26), ISBLANK(G26), ISBLANK(J26), ISBLANK('WEEK 2'!N27)), "", ROUNDUP((((D26 + G26 + J26) / 3) - 'WEEK 2'!N27) / 'WEEK 2'!N27 * 100, 0) & "% " & IF(((D26 + G26 + J26) / 3) - 'WEEK 2'!N27 > 0, "INCREASE", IF(((D26 + G26 + J26) / 3) - 'WEEK 2'!N27 < 0, "DECREASE", "NO CHANGE"))) -> -100% DECREASE
